Workbook

Sheet EMENDAS_CODIFICACAO
A1: id_emenda | B1: ano | C1: linha_origem | D1: arquivo_origem | E1: id_vereador_ano | F1: numero_emenda | G1: status_original | H1: parlamentar_original | I1: partido_base | J1: objeto_emenda | K1: dotacao_original | L1: uo_dec | M1: nome_uo | N1: func_dec | O1: nome_funcao | P1: sub_dec | Q1: nome_subfuncao | R1: prog_dec | S1: nome_programa | T1: acao_dec | U1: nome_acao | V1: nat_dec | W1: categoria_economica | X1: grupo_despesa | Y1: fonte_dec | Z1: orgao_executor | AA1: valor_emenda | AB1: valor_empenhado | AC1: valor_liquidado | AD1: valor_pago | AE1: credor_original | AF1: cnpj_credor_original | AG1: tipo_beneficiario_original | AH1: beneficiario_final_original | AI1: cnpj_beneficiario_final_original | AJ1: saude_orcamentaria | AK1: saude_tematica | AL1: subcodigo_cap_final | AM1: subcodigo_cap | AN1: subcodigo_cap_descricao | AO1: localidade_final | AP1: localidade_resumo | AQ1: N_localidades | AR1: georreferenciavel | AS1: georreferenciacao | AT1: publico_alvo_final | AU1: publico_alvo_resumo | AV1: credor_disponivel_final | AW1: credor_padronizado | AX1: status_codificacao | AY1: confianca | AZ1: data_codificacao | BA1: regra_decisao_id | BB1: cultura_ou_esporte
A2: 2022_ALVARO_DAMIAO_290_01 | B2: 2022 | C2: 4274 | D2: emendas_conslidadas(1).xlsx | E2: 2022_ALVARO_DAMIAO | F2: 290 | G2: Concluída | H2: Álvaro Damião | I2: DEM | J2: Ao reforço à dotação orçamentária para reforma e manutenção do Centro de Saúde Alcides Lins, localizado na rua Panema n. 275, bairro Concórdia; | K2: 2302.0400.10.122.117.1.216.449051 | L2: 2302 | M2: FUNDO MUNICIPAL DE SAÚDE | N2: 10 | O2: Saúde | P2: 122 | Q2: Administração Geral | R2: 0117 | S2: Gestão do SUS | T2: 1216 | U2: Construção, Ampliação e Reforma de Unidades de Saúde | V2: 449051 | W2: Despesa de capital | X2: Investimentos | Z2: SMSA | AA2: 400000 | AB2: 400000 | AC2: 240595 | AD2: 240595 | AE2: CONSTRUTORA CAMPOS E FILHOS LTDA | AF2: 15862332000152 | AG2: PBH | AH2: Município de Belo Horizonte | AI2: 18715383000140 | AJ2: 1 | AK2: 1 | AL2: 0322 | AM2: =IF(AL2="","",AL2&" - "&IFERROR(VLOOKUP(AL2,CODEBOOK_CAP!$C$2:$D$212,2,FALSE),"")) -> 0322 - ESTRUTURAS, HOSPITAIS, CLÍNICAS | AN2: =IF(AL2="","",IFERROR(VLOOKUP(AL2,CODEBOOK_CAP!$C$2:$E$212,3,FALSE),"")) -> Observações relacionadas as estruturas do sistema de saúde, como a construção de hospitais, postos de saúde, construção de maternidades, laboratórios, centros de saúde avançado, SAMU, Ambulâncias, UTI Móveis, leitos, compra de equipamentos médicos, Raio X, Ultrasom, equipamentos de diálise, capacidade de atendimento, estrutura e funcionamento de equipamentos públicos de saúde. | AO2: 1 | AP2: rua Panema n. 275, bairro Concórdia | AQ2: 1 | AR2: 1 | AS2: Centro de Saúde Alcides Lins, localizado na rua Panema n. 275, bairro Concórdia; | AT2: 0 | AV2: 1 | AW2: CONSTRUTORA CAMPOS E FILHOS LTDA | AX2: Pendente
A3: 2022_ALVARO_DAMIAO_291_01 | B3: 2022 | C3: 4275 | D3: emendas_conslidadas(1).xlsx | E3: 2022_ALVARO_DAMIAO | F3: 291 | G3: Concluída | H3: Álvaro Damião | I3: DEM | J3: Ao reforço à dotação orçamentária para reforma e manutenção do Centro de Saúde Cachoeirinha, estabelecido na rua Borborema n. 1325, bairro Cachoeirinha; | K3: 2302.0400.10.122.117.1.216.449051 | L3: 2302 | M3: FUNDO MUNICIPAL DE SAÚDE | N3: 10 | O3: Saúde | P3: 122 | Q3: Administração Geral | R3: 0117 | S3: Gestão do SUS | T3: 1216 | U3: Construção, Ampliação e Reforma de Unidades de Saúde | V3: 449051 | W3: Despesa de capital | X3: Investimentos | Z3: SMSA | AA3: 65000 | AB3: 59878 | AD3: 41513.2 | AE3: CONSTRUTORA CAMPOS E FILHOS LTDA | AF3: 15862332000152 | AG3: PBH | AH3: Município de Belo Horizonte | AI3: 18715383000140 | AJ3: 1 | AK3: 1 | AL3: 0322 | AM3: =IF(AL3="","",AL3&" - "&IFERROR(VLOOKUP(AL3,CODEBOOK_CAP!$C$2:$D$212,2,FALSE),"")) -> 0322 - ESTRUTURAS, HOSPITAIS, CLÍNICAS | AN3: =IF(AL3="","",IFERROR(VLOOKUP(AL3,CODEBOOK_CAP!$C$2:$E$212,3,FALSE),"")) -> Observações relacionadas as estruturas do sistema de saúde, como a construção de hospitais, postos de saúde, construção de maternidades, laboratórios, centros de saúde avançado, SAMU, Ambulâncias, UTI Móveis, leitos, compra de equipamentos médicos, Raio X, Ultrasom, equipamentos de diálise, capacidade de atendimento, estrutura e funcionamento de equipamentos públicos de saúde. | AO3: 1 | AP3: rua Borborema n. 1325, bairro Cachoeirinha | AQ3: 1 | AR3: 1 | AS3: Centro de Saúde Cachoeirinha, estabelecido na rua Borborema n. 1325, bairro Cachoeirinha; | AT3: 0 | AV3: 1 | AW3: CONSTRUTORA CAMPOS E FILHOS LTDA | AX3: Pendente
A4: 2022_ALVARO_DAMIAO_292_01 | B4: 2022 | C4: 4276 | D4: emendas_conslidadas(1).xlsx | E4: 2022_ALVARO_DAMIAO | F4: 292 | G4: Concluída | H4: Álvaro Damião | I4: DEM | J4: Destinação de recursos para o Instituto Cultural, Esportivo e Social Bacana Demais - ICESBADE, CNPJ: 20.997.880/0001-20, para a execução de atividades socioassistenciais, de acordo com o disposto na Lei Federal nº 8.742/93, em consonância com a referida inscrição no Conselho Municipal de Assistência Social de Belo Horizonte – CMAS-BH; | K4: 1011.1100.08.244.113.2.804.339039 | L4: 1011 | M4: FUNDO MUNICIPAL DE ASSISTÊNCIA SOCIAL | N4: 08 | O4: Assistência Social | P4: 244 | Q4: Assistência Comunitária | R4: 0113 | S4: Aprimoramento da Gestão do SUAS | T4: 2804 | U4: Gestão dos Equipamentos e Promoção Social | V4: 339039 | W4: Despesa corrente | X4: Outras despesas correntes | Z4: SMASDH | AA4: 640000 | AB4: 640000 | AC4: 640000 | AD4: 640000 | AE4: INSTITUTO CULTURAL ESPORTIVO E SOCIAL BACANA DEMAIS ICESBADE | AF4: 20997880000120 | AG4: Associações Diversas | AH4: Associações Diversas | AJ4: 0 | AK4: 0 | AL4: 1300 | AM4: =IF(AL4="","",AL4&" - "&IFERROR(VLOOKUP(AL4,CODEBOOK_CAP!$C$2:$D$212,2,FALSE),"")) -> 1300 - GERAL | AN4: =IF(AL4="","",IFERROR(VLOOKUP(AL4,CODEBOOK_CAP!$C$2:$E$212,3,FALSE),"")) -> Observações gerais sobre políticas sociais que envolvam mais de um casos dos subtópicos, políticas gerais de assistência social, welfare state, bem estar social, Ministérios e orcamentos como do Desenvolvimento social e combate e fome, desenvolvimento social, sistemas de gestão de políticas de assistencia, CAD UNICO, cadastros, sistemas computacionais para desenvolvimento de ações e políticas sociais, BPC - Benefício de Prestação Continuada geral para idosos e deficientes. NÃO CONFUNDIR POLÍTICAS SOCIAIS COM POLÍTICA DE EMPREGO E RENDA. Todas as questões, direitos, políticas que se relacionem com o TRABALHO como contrapartida, estão no código 5. Maternidade, Paternidade aposentadoria por tempo de serviço, INSS. | AO4: 0 | AQ4: 0 | AR4: 0 | AT4: 0 | AV4: 1 | AW4: INSTITUTO CULTURAL ESPORTIVO E SOCIAL BACANA DEMAIS ICESBADE | AX4: Pendente
A5: 2022_ALVARO_DAMIAO_293_01 | B5: 2022 | C5: 4277 | D5: emendas_conslidadas(1).xlsx | E5: 2022_ALVARO_DAMIAO | F5: 293 | G5: Concluída | H5: Álvaro Damião | I5: DEM | J5: Ao reforço à dotação orçamentária para reforma e manutenção do Centro de Saúde Efigênia Murta Figueiredo, localizado na Rua Serra do Cipó, 170, bairro Conjunto Ribeiro de Abreu; | K5: 2302.0400.10.122.117.1.216.449051 | L5: 2302 | M5: FUNDO MUNICIPAL DE SAÚDE | N5: 10 | O5: Saúde | P5: 122 | Q5: Administração Geral | R5: 0117 | S5: Gestão do SUS | T5: 1216 | U5: Construção, Ampliação e Reforma de Unidades de Saúde | V5: 449051 | W5: Despesa de capital | X5: Investimentos | Z5: SMSA | AA5: 250000 | AB5: 250000 | AC5: 151265.75 | AD5: 151265.75 | AE5: CONSTRUTORA CAMPOS E FILHOS LTDA | AF5: 15862332000152 | AG5: - | AH5: - | AI5: - | AJ5: 1 | AK5: 1 | AL5: 0322 | AM5: =IF(AL5="","",AL5&" - "&IFERROR(VLOOKUP(AL5,CODEBOOK_CAP!$C$2:$D$212,2,FALSE),"")) -> 0322 - ESTRUTURAS, HOSPITAIS, CLÍNICAS | AN5: =IF(AL5="","",IFERROR(VLOOKUP(AL5,CODEBOOK_CAP!$C$2:$E$212,3,FALSE),"")) -> Observações relacionadas as estruturas do sistema de saúde, como a construção de hospitais, postos de saúde, construção de maternidades, laboratórios, centros de saúde avançado, SAMU, Ambulâncias, UTI Móveis, leitos, compra de equipamentos médicos, Raio X, Ultrasom, equipamentos de diálise, capacidade de atendimento, estrutura e funcionamento de equipamentos públicos de saúde. | AO5: 1 | AP5: Rua Serra do Cipó, 170, bairro Conjunto Ribeiro de Abreu | AQ5: 1 | AR5: 1 | AS5: Centro de Saúde Efigênia Murta Figueiredo, localizado na Rua Serra do Cipó, 170, bairro Conjunto Ribeiro de Abreu; | AT5: 0 | AV5: 1 | AW5: CONSTRUTORA CAMPOS E FILHOS LTDA | AX5: Pendente
A6: 2022_ALVARO_DAMIAO_294_01 | B6: 2022 | C6: 4278 | D6: emendas_conslidadas(1).xlsx | E6: 2022_ALVARO_DAMIAO | F6: 294 | G6: Concluída | H6: Álvaro Damião | I6: DEM | J6: Ao recapeamento asfáltico no bairro Concórdia; | K6: 2700.1100.15.451.062.1.230.449051 | L6: 2700 | M6: SECRETARIA MUNICIPAL DE OBRAS E INFRAESTRUTURA | N6: 15 | O6: Urbanismo | P6: 451 | Q6: Infra-Estrutura Urbana | R6: 0062 | S6: Gestão do Sistema Viário Municipal | T6: 1230 | U6: Implantação e Reconstrução de Vias Públicas | V6: 449051 | W6: Despesa de capital | X6: Investimentos | Z6: SMOBI | AA6: 515000 | AB6: 515000 | AC6: 0 | AD6: 0 | AE6: LM CONSTRUCOES E PAVIMENTACOES LTDA | AF6: 1631484000130 | AG6: - | AH6: - | AI6: - | AJ6: 0 | AK6: 0 | AL6: 1002 | AM6: =IF(AL6="","",AL6&" - "&IFERROR(VLOOKUP(AL6,CODEBOOK_CAP!$C$2:$D$212,2,FALSE),"")) -> 1002 - CARROS, TRÂNSITO, CONSTRUÇÃO E MANUTENÇÃO DE RUAS E ESTRADAS | AN6: =IF(AL6="","",IFERROR(VLOOKUP(AL6,CODEBOOK_CAP!$C$2:$E$212,3,FALSE),"")) -> Construção, manutenção de ruas, avenidas, estradas. BRs, pedágios, privatizações, concessinárias, segurança nas estradas, leis de trânsito relacionadas a via, limite de velocidade, sinalização, recapeamento de ruas, pavimentação estradas de terra, não pavimentadas, acidentes e camapanhas de prevencao contra acidentes de transito. Observações sobre regulação de transportes não públicos de carros, veículos de passeio, uber, taxi, transporte de cargas terrestre, frete, trânsito em vias públicas, regulamentação de tipos de carteira de motorista, especificações para caminhoneiros, testes e exames de habilitação, exigências de carteira de habilitação, obrigatoriedade de itens em veículos (extintor, kit primeiros socorros, airbag, freios abs) Quando tratar de grandes obras de construções de rodovias, olhar codigo 1010 para ver qual se encaixa melhor. | AO6: 1 | AP6: bairro Concórdia | AQ6: 0 | AR6: 0 | AT6: 0 | AV6: 1 | AW6: LM CONSTRUCOES E PAVIMENTACOES LTDA | AX6: Pendente
A7: 2022_ALVARO_DAMIAO_295_01 | B7: 2022 | C7: 4279 | D7: emendas_conslidadas(1).xlsx | E7: 2022_ALVARO_DAMIAO | F7: 295 | G7: Cancelada | H7: Álvaro Damião | I7: DEM | J7: - | K7: - | Z7: Cancelada | AA7: 85000 | AE7: - | AF7: - | AG7: - | AH7: - | AI7: - | AM7: =IF(AL7="","",AL7&" - "&IFERROR(VLOOKUP(AL7,CODEBOOK_CAP!$C$2:$D$212,2,FALSE),"")) | AN7: =IF(AL7="","",IFERROR(VLOOKUP(AL7,CODEBOOK_CAP!$C$2:$E$212,3,FALSE),"")) | AX7: Pendente
A8: 2022_ALVARO_DAMIAO_296_01 | B8: 2022 | C8: 4280 | D8: emendas_conslidadas(1).xlsx | E8: 2022_ALVARO_DAMIAO | F8: 296 | G8: Cancelada | H8: Álvaro Damião | I8: DEM | J8: - | K8: - | Z8: Cancelada | AA8: 175000 | AE8: - | AF8: - | AG8: - | AH8: - | AI8: - | AM8: =IF(AL8="","",AL8&" - "&IFERROR(VLOOKUP(AL8,CODEBOOK_CAP!$C$2:$D$212,2,FALSE),"")) | AN8: =IF(AL8="","",IFERROR(VLOOKUP(AL8,CODEBOOK_CAP!$C$2:$E$212,3,FALSE),"")) | AX8: Pendente
A9: 2022_ALVARO_DAMIAO_297_01 | B9: 2022 | C9: 4281 | D9: emendas_conslidadas(1).xlsx | E9: 2022_ALVARO_DAMIAO | F9: 297 | G9: Cancelada | H9: Álvaro Damião | I9: DEM | J9: Ao recapeamento asfáltico da Rua Saquarema, no trecho situado entre as ruas Jequiriçá e Juparanã, com extensão aproximada de 100 m (cem metros) com 5 cm (cinco centímetros) de espessura, no Bairro Concórdia; | K9: - | Z9: Cancelada | AA9: 85000 | AE9: - | AF9: - | AG9: - | AH9: - | AI9: - | AK9: 0 | AL9: 1002 | AM9: =IF(AL9="","",AL9&" - "&IFERROR(VLOOKUP(AL9,CODEBOOK_CAP!$C$2:$D$212,2,FALSE),"")) -> 1002 - CARROS, TRÂNSITO, CONSTRUÇÃO E MANUTENÇÃO DE RUAS E ESTRADAS | AN9: =IF(AL9="","",IFERROR(VLOOKUP(AL9,CODEBOOK_CAP!$C$2:$E$212,3,FALSE),"")) -> Construção, manutenção de ruas, avenidas, estradas. BRs, pedágios, privatizações, concessinárias, segurança nas estradas, leis de trânsito relacionadas a via, limite de velocidade, sinalização, recapeamento de ruas, pavimentação estradas de terra, não pavimentadas, acidentes e camapanhas de prevencao contra acidentes de transito. Observações sobre regulação de transportes não públicos de carros, veículos de passeio, uber, taxi, transporte de cargas terrestre, frete, trânsito em vias públicas, regulamentação de tipos de carteira de motorista, especificações para caminhoneiros, testes e exames de habilitação, exigências de carteira de habilitação, obrigatoriedade de itens em veículos (extintor, kit primeiros socorros, airbag, freios abs) Quando tratar de grandes obras de construções de rodovias, olhar codigo 1010 para ver qual se encaixa melhor. | AO9: 1 | AP9: Rua Saquarema, no trecho situado entre as ruas Jequiriçá e Juparanã, com extensão aproximada de 100 m (cem metros) com 5 cm (cinco centímetros) de espessura, no Bairro Concórdia; | AQ9: 1 | AR9: 1 | AS9: Rua Saquarema, no trecho situado entre as ruas Jequiriçá e Juparanã, com extensão aproximada de 100 m (cem metros) com 5 cm (cinco centímetros) de espessura, no Bairro Concórdia; | AT9: 0 | AX9: Pendente
A10: 2022_ALVARO_DAMIAO_298_01 | B10: 2022 | C10: 4282 | D10: emendas_conslidadas(1).xlsx | E10: 2022_ALVARO_DAMIAO | F10: 298 | G10: Cancelada | H10: Álvaro Damião | I10: DEM | J10: Ao recapeamento asfáltico da Rua Jacuípe, no trecho situado entre as ruas Itaquera e Itapeva, com extensão aproximada de 100 m (cem metros) e 5 cm (cinco centímetros) de espessura, no Bairro Concórdia; | K10: - | Z10: Cancelada | AA10: 85000 | AE10: - | AF10: - | AG10: - | AH10: - | AI10: - | AK10: 0 | AL10: 1002 | AM10: =IF(AL10="","",AL10&" - "&IFERROR(VLOOKUP(AL10,CODEBOOK_CAP!$C$2:$D$212,2,FALSE),"")) -> 1002 - CARROS, TRÂNSITO, CONSTRUÇÃO E MANUTENÇÃO DE RUAS E ESTRADAS | AN10: =IF(AL10="","",IFERROR(VLOOKUP(AL10,CODEBOOK_CAP!$C$2:$E$212,3,FALSE),"")) -> Construção, manutenção de ruas, avenidas, estradas. BRs, pedágios, privatizações, concessinárias, segurança nas estradas, leis de trânsito relacionadas a via, limite de velocidade, sinalização, recapeamento de ruas, pavimentação estradas de terra, não pavimentadas, acidentes e camapanhas de prevencao contra acidentes de transito. Observações sobre regulação de transportes não públicos de carros, veículos de passeio, uber, taxi, transporte de cargas terrestre, frete, trânsito em vias públicas, regulamentação de tipos de carteira de motorista, especificações para caminhoneiros, testes e exames de habilitação, exigências de carteira de habilitação, obrigatoriedade de itens em veículos (extintor, kit primeiros socorros, airbag, freios abs) Quando tratar de grandes obras de construções de rodovias, olhar codigo 1010 para ver qual se encaixa melhor. | AO10: 1 | AP10: Rua Jacuípe, no trecho situado entre as ruas Itaquera e Itapeva, com extensão aproximada de 100 m (cem metros) e 5 cm (cinco centímetros) de espessura, no Bairro Concórdia; | AQ10: 1 | AR10: 1 | AS10: Rua Jacuípe, no trecho situado entre as ruas Itaquera e Itapeva, com extensão aproximada de 100 m (cem metros) e 5 cm (cinco centímetros) de espessura, no Bairro Concórdia; | AT10: 0 | AX10: Pendente
A11: 2022_ALVARO_DAMIAO_299_01 | B11: 2022 | C11: 4283 | D11: emendas_conslidadas(1).xlsx | E11: 2022_ALVARO_DAMIAO | F11: 299 | G11: Concluída | H11: Álvaro Damião | I11: DEM | J11: Ao reforço de dotação orçamentária da Empresa Municipal de Turismo de Belo Horizonte S/A visando o desenvolvimento econômico do turismo e o fomento do carnaval em Belo Horizonte; | K11: 2805.1100.23.695.086.2.629.339039 | L11: 2805 | M11: EMPRESA MUNICIPAL DE TURISMO DE BELO HORIZONTE S/A | N11: 23 | O11: Comércio e Serviços | P11: 695 | Q11: Turismo | R11: 0086 | S11: Fomento ao Turismo de Lazer, Eventos e Negócios | T11: 2629 | U11: Desenvolvimento e Promoção do Turismo | V11: 339039 | W11: Despesa corrente | X11: Outras despesas correntes | Z11: BELOTUR | AA11: 129000 | AB11: 129000 | AC11: 129000 | AD11: 129000 | AE11: LOCABET MAQUINAS E EQUIPAMENTOS LTDA | AF11: 3778642000104 | AG11: PBH | AH11: Município de Belo Horizonte | AI11: 18715383000140 | AJ11: 0 | AK11: 0 | AL11: 1524 | AM11: =IF(AL11="","",AL11&" - "&IFERROR(VLOOKUP(AL11,CODEBOOK_CAP!$C$2:$D$212,2,FALSE),"")) -> 1524 - TURISMO | AN11: =IF(AL11="","",IFERROR(VLOOKUP(AL11,CODEBOOK_CAP!$C$2:$E$212,3,FALSE),"")) -> Assuntos que se relacionam com a política de desenvolvimento de turismo, cidades turisticas, obras turisticas, assuntos relacioandos a incentismo aos turismo, apoios setoriais para promocao de turismo, visto de turismo, promoção do turismo brasileiro. | AO11: 0 | AQ11: 0 | AR11: 0 | AT11: 0 | AX11: Pendente
A12: 2022_BELLA_GONCALVES_607_01 | B12: 2022 | C12: 4548 | D12: emendas_conslidadas(1).xlsx | E12: 2022_BELLA_GONCALVES | F12: 607 | G12: Concluída | H12: Bella Gonçalves | I12: PSOL | J12: Ao reforço da subação 0001 - Política Municipal Cultura Viva, inserida na ação 2930 - Promoção e democratização do acesso à cultura e no programa 0154 - Promoção e Acesso às Artes e à Cultura; | K12: 3100.13.392.154.2930.339039 | L12: 3100 | M12: SECRETARIA MUNICIPAL DE CULTURA | N12: 13 | O12: Cultura | P12: 392 | Q12: Difusão Cultural | R12: 0154 | S12: Promoção e Acesso às Artes e à Cultura | T12: 2930 | U12: PROMOÇÃO E DEMOCRATIZAÇÃO DO ACESSO À CULTURA | V12: 339039 | W12: Despesa corrente | X12: Outras despesas correntes | Z12: SMC | AA12: 300000 | AB12: 300000 | AC12: 300000 | AD12: 300000 | AE12: ASSOCIACAO MOVIMENTO DE TEATRO DE GRUPO DE MINAS GERAIS ASSOCIACAO DE RESISTENCIA CULTURAL DA COMUNIDADE QUILOMBOLA MANZO NGUNZO KAIANGO ASSOCIACAO DE RESISTENCIA CULTURAL DA COMUNIDADE QUILOMBOLA MANZO NGUNZO KAIANGO | AF12: 00784491000109 07981042000108 07981042000108 | AG12: PBH | AH12: Município de Belo Horizonte | AI12: 18715383000140 | AJ12: 0 | AK12: 0 | AL12: 2300 | AM12: =IF(AL12="","",AL12&" - "&IFERROR(VLOOKUP(AL12,CODEBOOK_CAP!$C$2:$D$212,2,FALSE),"")) -> 2300 - GERAL | AN12: =IF(AL12="","",IFERROR(VLOOKUP(AL12,CODEBOOK_CAP!$C$2:$E$212,3,FALSE),"")) -> Observações relativas as políticas de cultura, Lei rouanet, patrimônio cultural, imaterial, políticas de artes, incentivos fiscais para artes, promoção de eventos culturais, amostras, teatro, dança, artes plásticas, artes visuais, museus, galerias públicas, idioma, lingua portuguesa. Grandes eventos esportivos, Copa do Mundo, Olimpiadas, Esporte e Lazer. | AO12: 0 | AQ12: 0 | AR12: 0 | AT12: 0 | AX12: Pendente | BB12: cultura
A13: 2022_BELLA_GONCALVES_634_01 | B13: 2022 | C13: 4573 | D13: emendas_conslidadas(1).xlsx | E13: 2022_BELLA_GONCALVES | F13: 634 | G13: Concluída | H13: Bella Gonçalves | I13: PSOL | J13: Ao reforço da subação 0006 atendimento da população na rede de saúde mental; ação 2891 rede especializada; programa 0114 Atenção secundária e terciária à saúde; | K13: 2302.10.302.114.2891.339039 | L13: 2302 | M13: FUNDO MUNICIPAL DE SAÚDE | N13: 10 | O13: Saúde | P13: 302 | Q13: Assistência Hospitalar e Ambulatorial | R13: 0114 | S13: Atenção Secundária e Terciária à Saúde | T13: 2891 | U13: Rede Especializada | V13: 339039 | W13: Despesa corrente | X13: Outras despesas correntes | Z13: SMSA | AA13: 1064319 | AB13: 1064319 | AC13: 1064319 | AD13: 1064319 | AE13: NUTRIVIP ALIMENTACAO LTDA. ORGANIZACOES PAULA E CASTRO LTDA ASSOCIACAO DE TRABALHO E PRODUCAO SOLIDARIA - SURICATO MOVIMENTO DE PROMOCAO E ASSISTENCIA SOCIAL SOPAO MINEIRO CARITAS BRASILEIRA CARITAS BRASILEIRA CONSORCIO OPERACIONAL DO TRANSPORTE COLETIVO DE PASSAGEIROS POR ONIBUS DO MUNICIPIO DE BELO HORIZONTE CONSORCIO OPERACIONAL DO TRANSPORTE COLETIVO DE PASSAGEIROS POR ONIBUS DO MUNICIPIO DE BELO HORIZONTE | AF13: 09487591000571 01940433000270 08808991000145 38731899000195 33654419000892 33654419000892 04398505000107 04398505000107 | AG13: PBH | AH13: Município de Belo Horizonte | AI13: 18715383000140 | AJ13: 1 | AK13: 1 | AL13: 0333 | AM13: =IF(AL13="","",AL13&" - "&IFERROR(VLOOKUP(AL13,CODEBOOK_CAP!$C$2:$D$212,2,FALSE),"")) -> 0333 - SAÚDE MENTAL | AN13: =IF(AL13="","",IFERROR(VLOOKUP(AL13,CODEBOOK_CAP!$C$2:$E$212,3,FALSE),"")) -> Serviços de atendimento a saúde mental e psico-social. CAPS, Controle de qualidade mental, esquizofrenia, bipolaridade, transtornos mentais, ansiedade, alucinançao, depressão, suicídio, CVV, atendimento psicológico e psiquiátrico, sanatório, manicomio. Não confundir com dependências de alcool (342) e drogas (343) | AO13: 0 | AQ13: 0 | AR13: 0 | AT13: 0 | AX13: Pendente
A14: 2022_BELLA_GONCALVES_674_01 | B14: 2022 | C14: 4612 | D14: emendas_conslidadas(1).xlsx | E14: 2022_BELLA_GONCALVES | F14: 674 | G14: Concluída | H14: Bella Gonçalves | I14: PSOL | J14: Ao reforço de dotação orçamentária na subação 004 (Implantação e agricultura em Unidades Produtivas Coletivas/Comunitárias), ação 2121 (Fortalecimento da Produção da Agricultura Urbana Agroecológica), 308 (BH Cidade Sustentável: Mobilizar, Educar e Cultivar Alimentação Saudável) para implantação e manutenção de Sistemas de produção agroecológicos nos 5 Territórios Quilombolas de Belo Horizonte: Quilombo Mangueiras, Quilombo Luízes, Quilombo Manzo Ngunzo Kaiango e Quilombo Souza e Quilombo Matia; | K14: 1010.20.608.308.2121.339039 | L14: 1010 | M14: FUNDO MUNICIPAL DE SEGURANÇA ALIMENTAR E NUTRICIONAL | N14: 20 | O14: Agricultura | P14: 608 | Q14: Promoção da Produção Agropecuária | R14: 0308 | S14: BH Cidade Sustentável: Mobilizar, Educar e Cultivar Alimentação Saudável | T14: 2121 | U14: Fortalecimento da Produção da Agricultura Urbana Agroecológica | V14: 339039 | W14: Despesa corrente | X14: Outras despesas correntes | Z14: SMASDH | AA14: 200000 | AB14: 200000 | AC14: 200000 | AD14: 200000 | AE14: BAMBUZERIA CRUZEIRO DO SUL BAMBUZERIA CRUZEIRO DO SUL | AF14: 03211130000161 03211130000161 | AG14: PBH | AH14: Município de Belo Horizonte | AI14: 18715383000140 | AJ14: 0 | AK14: 0 | AL14: 2102 | AM14: =IF(AL14="","",AL14&" - "&IFERROR(VLOOKUP(AL14,CODEBOOK_CAP!$C$2:$D$212,2,FALSE),"")) -> 2102 - POPULAÇÕES TRADICIONAIS BRASILEIRAS - INDÍGENAS, QUILOMBOLAS, RIBEIRINHOS, SERINGUEIROS, CAIÇARAS | AN14: =IF(AL14="","",IFERROR(VLOOKUP(AL14,CODEBOOK_CAP!$C$2:$E$212,3,FALSE),"")) -> Todos os temas, de todas as políticas setoriais que envolvam populações tradicionais nativas brasileiras. Temas relacionados ao uso da terra por populações nativas como uso de terra por indígenas e reservas indígenas, quilombolas e populações ribeirinhas. Saude, educacao, assistencia, terras. Populações Nativas não se codifica em política setoria, mas sim aqui! | AO14: 1 | AP14: 5 Territórios Quilombolas de Belo Horizonte: Quilombo Mangueiras, Quilombo Luízes, Quilombo Manzo Ngunzo Kaiango e Quilombo Souza e Quilombo Matia | AQ14: 5 | AR14: 1 | AS14: 5 Territórios Quilombolas de Belo Horizonte: Quilombo Mangueiras, Quilombo Luízes, Quilombo Manzo Ngunzo Kaiango e Quilombo Souza e Quilombo Matia | AT14: 1 | AU14: quilombolas | AX14: Pendente
A15: 2022_BELLA_GONCALVES_684_01 | B15: 2022 | C15: 4617 | D15: emendas_conslidadas(1).xlsx | E15: 2022_BELLA_GONCALVES | F15: 684 | G15: Concluída | H15: Bella Gonçalves | I15: PSOL | J15: Ao reforço de dotação orçamentária para a subação 0004 - CENTRO DE EDUCAÇÃO AMBIENTAL DE INCLUSÃO PRODUTIVA VOLTADA PARA EMPREGOS VERDES; ação: 2913 - Capacitação e Conscientização Ambiental. promoção de sustentabilidade, educação ambiental; Programa 0307 - SUSTENTABILIDADE, EDUCAÇÃO AMBIENTAL E MODERNIZAÇÃO DA GESTÃO AMBIENTAL visando a gestão ambiental nos quilombos urbanos de Belo Horizonte; | K15: 2500.18.541.307.2913.339039 | L15: 2500 | M15: SECRETARIA MUNICIPAL DE MEIO AMBIENTE | N15: 18 | O15: Gestão Ambiental | P15: 541 | Q15: Preservação e Conservação Ambiental | R15: 0307 | S15: Sustentabilidade, Educação Ambiental e Modernização da Gestão Ambiental | T15: 2913 | U15: Capacitação e Conscientização Ambiental | V15: 339039 | W15: Despesa corrente | X15: Outras despesas correntes | Z15: SMMA | AA15: 500000 | AB15: 0 | AC15: 0 | AD15: 0 | AG15: PBH | AH15: Município de Belo Horizonte | AI15: 18715383000140 | AJ15: 0 | AK15: 0 | AL15: 2102 | AM15: =IF(AL15="","",AL15&" - "&IFERROR(VLOOKUP(AL15,CODEBOOK_CAP!$C$2:$D$212,2,FALSE),"")) -> 2102 - POPULAÇÕES TRADICIONAIS BRASILEIRAS - INDÍGENAS, QUILOMBOLAS, RIBEIRINHOS, SERINGUEIROS, CAIÇARAS | AN15: =IF(AL15="","",IFERROR(VLOOKUP(AL15,CODEBOOK_CAP!$C$2:$E$212,3,FALSE),"")) -> Todos os temas, de todas as políticas setoriais que envolvam populações tradicionais nativas brasileiras. Temas relacionados ao uso da terra por populações nativas como uso de terra por indígenas e reservas indígenas, quilombolas e populações ribeirinhas. Saude, educacao, assistencia, terras. Populações Nativas não se codifica em política setoria, mas sim aqui! | AO15: 0 | AQ15: 0 | AR15: 0 | AT15: 1 | AU15: quilombolas | AX15: Pendente
A16: 2022_BELLA_GONCALVES_730_01 | B16: 2022 | C16: 4663 | D16: emendas_conslidadas(1).xlsx | E16: 2022_BELLA_GONCALVES | F16: 730 | G16: Concluída | H16: Bella Gonçalves | I16: PSOL | J16: Ao reforço de dotação orçamentária para garantia do acesso ao direito de retificação do social para pessoas travestis e/ou transexuais; | K16: 1000.14.422.127.2928.339039 | L16: 1000 | M16: SECRETARIA MUNICIPAL DE ASSISTÊNCIA SOCIAL, SEGURANÇA ALIMENTAR E CIDADANIA | N16: 14 | O16: Direitos da Cidadania | P16: 422 | Q16: Direitos Individuais, Coletivos e Difusos | R16: 0127 | S16: Promoção e Defesa de Direitos Humanos e Cidadania | T16: 2928 | U16: Promoção, Proteção e Defesa das pessoas LGBT | V16: 339039 | W16: Despesa corrente | X16: Outras despesas correntes | Z16: SMASDH | AA16: 100000 | AB16: 40000 | AC16: 40000 | AD16: 40000 | AE16: INSTITUTO DE PROMOCAO SOCIAL E HUMANA DARCY RIBEIRO | AF16: 00794227000156 | AG16: PBH | AH16: Município de Belo Horizonte | AI16: 18715383000140 | AJ16: 0 | AK16: 0 | AL16: 0202 | AM16: =IF(AL16="","",AL16&" - "&IFERROR(VLOOKUP(AL16,CODEBOOK_CAP!$C$2:$D$212,2,FALSE),"")) -> 0202 - DISCRIMINAÇÃO POR GÊNERO OU ORIENTAÇÃO SEXUAL (MISOGINIA E HOMOFOBIA) | AN16: =IF(AL16="","",IFERROR(VLOOKUP(AL16,CODEBOOK_CAP!$C$2:$E$212,3,FALSE),"")) -> Políticas de promoção de igualdade de gênero e de igualdade de relações sociais relacionadas a gênero e orientação sexual. Misoginia, Homofobia, ataques homofóbicos, casamento homoafetivo, igualdade salarial para mulheres, igualdade de trabalho para mulheres, feminismo, Parada LGBT, LGBTQI, transexuais, homossexuais, bissexuais, travestis, relações de gênero com emprego ( tipos de posições, renda, promoção , salário) . VIOLÊNCIA DOMESTICA contra mulheres deve ser codificado em 1208 | AO16: 0 | AQ16: 0 | AR16: 0 | AT16: 1 | AU16: trans/travestis | AX16: Pendente
A17: 2022_BELLA_GONCALVES_746_01 | B17: 2022 | C17: 4676 | D17: emendas_conslidadas(1).xlsx | E17: 2022_BELLA_GONCALVES | F17: 746 | G17: Concluída | H17: Bella Gonçalves | I17: PSOL | J17: Ao reforço de dotação orçamentária para a Subação 0005 - PROMOÇÃO, PROTEÇÃO E DEFESA DE DIREITOS HUMANOS E CIDADANIA com foco em ações de formação, capacitação, serviços, cursos, programas, projetos e benefícios mitigadores de vulnerabilidade social para a população LGBTQl; | K17: 1019.14.422.127.2335.339036 | L17: 1019 | M17: FUNDO MUNICIPAL DE PROTEÇÃO E DEFESA DAS MINORIAS | N17: 14 | O17: Direitos da Cidadania | P17: 422 | Q17: Direitos Individuais, Coletivos e Difusos | R17: 0127 | S17: Promoção e Defesa de Direitos Humanos e Cidadania | T17: 2335 | U17: Gestão da Política de Direitos Humanos e de Cidadania | V17: 339036 | W17: Despesa corrente | X17: Outras despesas correntes | Z17: SMASDH | AA17: 100000 | AB17: 99400 | AC17: 99400 | AD17: 99400 | AE17: F ALVES DE QUEIROZ LTDA | AF17: 17599187000194 | AG17: PBH | AH17: Município de Belo Horizonte | AI17: 18715383000140 | AJ17: 0 | AK17: 0 | AL17: 0202 | AM17: =IF(AL17="","",AL17&" - "&IFERROR(VLOOKUP(AL17,CODEBOOK_CAP!$C$2:$D$212,2,FALSE),"")) -> 0202 - DISCRIMINAÇÃO POR GÊNERO OU ORIENTAÇÃO SEXUAL (MISOGINIA E HOMOFOBIA) | AN17: =IF(AL17="","",IFERROR(VLOOKUP(AL17,CODEBOOK_CAP!$C$2:$E$212,3,FALSE),"")) -> Políticas de promoção de igualdade de gênero e de igualdade de relações sociais relacionadas a gênero e orientação sexual. Misoginia, Homofobia, ataques homofóbicos, casamento homoafetivo, igualdade salarial para mulheres, igualdade de trabalho para mulheres, feminismo, Parada LGBT, LGBTQI, transexuais, homossexuais, bissexuais, travestis, relações de gênero com emprego ( tipos de posições, renda, promoção , salário) . VIOLÊNCIA DOMESTICA contra mulheres deve ser codificado em 1208 | AO17: 0 | AQ17: 0 | AR17: 0 | AT17: 1 | AU17: LGBT | AX17: Pendente
A18: 2022_BELLA_GONCALVES_747_01 | B18: 2022 | C18: 4677 | D18: emendas_conslidadas(1).xlsx | E18: 2022_BELLA_GONCALVES | F18: 747 | G18: Concluída | H18: Bella Gonçalves | I18: PSOL | J18: Ao reforço de dotação orçamentária da Subação 0005 - PROMOÇÃO, PROTEÇÃO E DEFESA DE DIREITOS HUMANOS E CIDADANIA com foco em ações de formação, capacitação, serviços, cursos, oficinas e projetos, a partir referências de notório saber popular, voltadas às minorias; | K18: 1019.14.422.127.2335.339036 | L18: 1019 | M18: FUNDO MUNICIPAL DE PROTEÇÃO E DEFESA DAS MINORIAS | N18: 14 | O18: Direitos da Cidadania | P18: 422 | Q18: Direitos Individuais, Coletivos e Difusos | R18: 0127 | S18: Promoção e Defesa de Direitos Humanos e Cidadania | T18: 2335 | U18: Gestão da Política de Direitos Humanos e de Cidadania | V18: 339036 | W18: Despesa corrente | X18: Outras despesas correntes | Z18: SMASDH | AA18: 89220 | AB18: 78900 | AC18: 77940 | AD18: 77940 | AE18: F ALVES DE QUEIROZ LTDA | AF18: 17599187000194 | AG18: PBH | AH18: Município de Belo Horizonte | AI18: 18715383000140 | AJ18: 0 | AK18: 0 | AL18: 0200 | AM18: =IF(AL18="","",AL18&" - "&IFERROR(VLOOKUP(AL18,CODEBOOK_CAP!$C$2:$D$212,2,FALSE),"")) -> 0200 - GERAL | AN18: =IF(AL18="","",IFERROR(VLOOKUP(AL18,CODEBOOK_CAP!$C$2:$E$212,3,FALSE),"")) -> Quando há combinação de diversos assuntos relacionado aos direitos civis, liberdade e atores indetificados como minorias. Questões gerais e amplas tais como Comissões, violações de direitos sem especificação, criação ou modificação ou atuação de Ministérios, departamentos ou instituições gerais, direito a propriedade privada, violação e atentados contra direitos civis em geral, cotas gerais (quando existem várias linhas, nao apenas racial), coberturas jornalisticas, estatisticas sobre minorias e sobre direitos básicos, discriminações e preconceito gerais sobre múltiplos aspectos. Quando o tema abordado for sobre uma única parte (sexo ou raça ou idade ou deficiência, codificar nos subcódigos específicos. Geral somente quando há combinação de fatores. Quando aparecer DIREITOS HUMANOS e assuntos de direito civil internacional, codificar em 1925. | AO18: 0 | AQ18: 0 | AR18: 0 | AT18: 0 | AX18: Pendente
A19: 2022_BELLA_GONCALVES_860_01 | B19: 2022 | C19: 4781 | D19: emendas_conslidadas(1).xlsx | E19: 2022_BELLA_GONCALVES | F19: 860 | G19: Concluída | H19: Bella Gonçalves | I19: PSOL | J19: Ao reforço de dotação do projeto Arte de Saúde da Rede de Saúde Mental; | K19: 2302.10.302.114.2891.335043 | L19: 2302 | M19: FUNDO MUNICIPAL DE SAÚDE | N19: 10 | O19: Saúde | P19: 302 | Q19: Assistência Hospitalar e Ambulatorial | R19: 0114 | S19: Atenção Secundária e Terciária à Saúde | T19: 2891 | U19: Rede Especializada | V19: 335043 | W19: Despesa corrente | X19: Outras despesas correntes | Z19: SMSA | AA19: 224901 | AB19: 224901 | AC19: 224901 | AD19: 224901 | AE19: CARITAS BRASILEIRA | AF19: 33654419000892 | AG19: PBH | AH19: Município de Belo Horizonte | AI19: 18715383000140 | AJ19: 1 | AK19: 1 | AL19: 0333 | AM19: =IF(AL19="","",AL19&" - "&IFERROR(VLOOKUP(AL19,CODEBOOK_CAP!$C$2:$D$212,2,FALSE),"")) -> 0333 - SAÚDE MENTAL | AN19: =IF(AL19="","",IFERROR(VLOOKUP(AL19,CODEBOOK_CAP!$C$2:$E$212,3,FALSE),"")) -> Serviços de atendimento a saúde mental e psico-social. CAPS, Controle de qualidade mental, esquizofrenia, bipolaridade, transtornos mentais, ansiedade, alucinançao, depressão, suicídio, CVV, atendimento psicológico e psiquiátrico, sanatório, manicomio. Não confundir com dependências de alcool (342) e drogas (343) | AO19: 0 | AQ19: 0 | AR19: 0 | AT19: 0 | AX19: Pendente
A20: 2022_BIM_DA_AMBULANCIA_780_01 | B20: 2022 | C20: 4708 | D20: emendas_conslidadas(1).xlsx | E20: 2022_BIM_DA_AMBULANCIA | F20: 780 | G20: Concluída | H20: Bim da Ambulância | I20: PSD | J20: Destinação de recursos para a Associação Mineira de Educação Continuada - ASMEC, CNPJ: 05.263.848/0001-27, para a execução de atividades socioassistenciais, de acordo com o disposto na Lei Federal nº 8.742/93, em consonância com a referida inscrição no Conselho Municipal de Assistência Social de Belo Horizonte – CMAS-BH; | K20: 1011.08.244.113.2804.339039 | L20: 1011 | M20: FUNDO MUNICIPAL DE ASSISTÊNCIA SOCIAL | N20: 08 | O20: Assistência Social | P20: 244 | Q20: Assistência Comunitária | R20: 0113 | S20: Aprimoramento da Gestão do SUAS | T20: 2804 | U20: Gestão dos Equipamentos e Promoção Social | V20: 339039 | W20: Despesa corrente | X20: Outras despesas correntes | Z20: SMASDH | AA20: 644610 | AB20: 644610 | AC20: 644610 | AD20: 644610 | AE20: ASSOCIACAO MINEIRA DE EDUCACAO CONTINUADA ASMEC ASSOCIACAO MINEIRA DE EDUCACAO CONTINUADA ASMEC | AF20: 05263848000127 05263848000127 | AG20: Associações Diversas | AH20: Associações Diversas | AJ20: 0 | AK20: 0 | AL20: 1300 | AM20: =IF(AL20="","",AL20&" - "&IFERROR(VLOOKUP(AL20,CODEBOOK_CAP!$C$2:$D$212,2,FALSE),"")) -> 1300 - GERAL | AN20: =IF(AL20="","",IFERROR(VLOOKUP(AL20,CODEBOOK_CAP!$C$2:$E$212,3,FALSE),"")) -> Observações gerais sobre políticas sociais que envolvam mais de um casos dos subtópicos, políticas gerais de assistência social, welfare state, bem estar social, Ministérios e orcamentos como do Desenvolvimento social e combate e fome, desenvolvimento social, sistemas de gestão de políticas de assistencia, CAD UNICO, cadastros, sistemas computacionais para desenvolvimento de ações e políticas sociais, BPC - Benefício de Prestação Continuada geral para idosos e deficientes. NÃO CONFUNDIR POLÍTICAS SOCIAIS COM POLÍTICA DE EMPREGO E RENDA. Todas as questões, direitos, políticas que se relacionem com o TRABALHO como contrapartida, estão no código 5. Maternidade, Paternidade aposentadoria por tempo de serviço, INSS. | AO20: 0 | AQ20: 0 | AR20: 0 | AT20: 1 | AU20: criancas e adolescentes | AX20: Pendente
A21: 2022_BIM_DA_AMBULANCIA_788_01 | B21: 2022 | C21: 4716 | D21: emendas_conslidadas(1).xlsx | E21: 2022_BIM_DA_AMBULANCIA | F21: 788 | G21: Impedimento Técnico | H21: Bim da Ambulância | I21: PSD | J21: Reforço à dotação para reforma do Campo de Futebol Milan, localizado na Rua Flávio Sampaio, 408, no bairro Serra Verde; | K21: - | Z21: Impedimento Técnico | AA21: 217000 | AE21: - | AG21: PBH | AH21: Município de Belo Horizonte | AI21: 18715383000140 | AJ21: 0 | AK21: 0 | AL21: 2300 | AM21: =IF(AL21="","",AL21&" - "&IFERROR(VLOOKUP(AL21,CODEBOOK_CAP!$C$2:$D$212,2,FALSE),"")) -> 2300 - GERAL | AN21: =IF(AL21="","",IFERROR(VLOOKUP(AL21,CODEBOOK_CAP!$C$2:$E$212,3,FALSE),"")) -> Observações relativas as políticas de cultura, Lei rouanet, patrimônio cultural, imaterial, políticas de artes, incentivos fiscais para artes, promoção de eventos culturais, amostras, teatro, dança, artes plásticas, artes visuais, museus, galerias públicas, idioma, lingua portuguesa. Grandes eventos esportivos, Copa do Mundo, Olimpiadas, Esporte e Lazer. | AO21: 1 | AP21: Rua Flávio Sampaio, 408, no bairro Serra Verde | AQ21: 1 | AR21: 1 | AS21: Campo de Futebol Milan, localizado na Rua Flávio Sampaio, 408, no bairro Serra Verde | AT21: 0 | AX21: Pendente | BB21: esporte e lazer
A22: 2022_BIM_DA_AMBULANCIA_789_01 | B22: 2022 | C22: 4717 | D22: emendas_conslidadas(1).xlsx | E22: 2022_BIM_DA_AMBULANCIA | F22: 789 | G22: Cancelada | H22: Bim da Ambulância | I22: PSD | J22: Reforço à dotação para reforma do Campo no bairro Serra Verde, localizado na Rua Guido Leão, 501 no bairro Serra Verde; | K22: - | Z22: Cancelada | AA22: 217000 | AE22: - | AF22: - | AG22: PBH | AH22: Município de Belo Horizonte | AI22: 18715383000140 | AJ22: 0 | AK22: 0 | AL22: 2300 | AM22: =IF(AL22="","",AL22&" - "&IFERROR(VLOOKUP(AL22,CODEBOOK_CAP!$C$2:$D$212,2,FALSE),"")) -> 2300 - GERAL | AN22: =IF(AL22="","",IFERROR(VLOOKUP(AL22,CODEBOOK_CAP!$C$2:$E$212,3,FALSE),"")) -> Observações relativas as políticas de cultura, Lei rouanet, patrimônio cultural, imaterial, políticas de artes, incentivos fiscais para artes, promoção de eventos culturais, amostras, teatro, dança, artes plásticas, artes visuais, museus, galerias públicas, idioma, lingua portuguesa. Grandes eventos esportivos, Copa do Mundo, Olimpiadas, Esporte e Lazer. | AO22: 1 | AP22: Rua Guido Leão, 501 no bairro Serra Verde; | AQ22: 1 | AR22: 1 | AS22: Campo no bairro Serra Verde, localizado na Rua Guido Leão, 501 no bairro Serra Verde; | AT22: 0 | AX22: Pendente | BB22: esporte e lazer
A23: 2022_BIM_DA_AMBULANCIA_853_01 | B23: 2022 | C23: 4775 | D23: emendas_conslidadas(1).xlsx | E23: 2022_BIM_DA_AMBULANCIA | F23: 853 | G23: Concluída | H23: Bim da Ambulância | I23: PSD | J23: Aquisição de kit EPI para a guarda municipal com destinação de R$66.000 segundo subação 0001 da ação 2802; | K23: 2100.06.122.109.2802.449052 | L23: 2100 | M23: SECRETARIA MUNICIPAL DE SEGURANÇA E PREVENÇÃO | N23: 06 | O23: Segurança Pública | P23: 122 | Q23: Administração Geral | R23: 0109 | S23: Operacionalização dos serviços de segurança | T23: 2802 | U23: Gestão da Política de Segurança e Prevenção | V23: 449052 | W23: Despesa de capital | X23: Investimentos | Z23: SMSP | AA23: 66000 | AB23: 65039 | AC23: 0 | AD23: 65039 | AE23: O. FILIZZOLA CIA. LTDA. EPP | AF23: 61182424000109 | AG23: - | AH23: - | AI23: - | AJ23: 0 | AK23: 0 | AL23: 1201 | AM23: =IF(AL23="","",AL23&" - "&IFERROR(VLOOKUP(AL23,CODEBOOK_CAP!$C$2:$D$212,2,FALSE),"")) -> 1201 - POLÍCIA, AGENCIAS E INSTITUIÇÕES - LEI E CRIMES | AN23: =IF(AL23="","",IFERROR(VLOOKUP(AL23,CODEBOOK_CAP!$C$2:$E$212,3,FALSE),"")) -> Questões relacionadas aos atores, intituições, agencias e agentes que atuam em questões relacionadas a justiça, lei, crime e violência. Servicos e instituições de apoio civil. Assuntos relacionados a atuação de Bombeiros, socorristas, guarda floresta, guarda costeira e proteção civil. Ministério Público, Ministério da Justiça, Polícia Federal, Tribunal de Contas, inteligência, proteção a vítimas, delação premiada, sistemas e banco de dados de justiça, computação vinculada a sistemas de combate a crimes e fraudes. Aqui a observação é sobre as INSTITUIÇÕES EM SI, e não sobre o assunto do qual ela trata, Os assuntos estão nos próximos sub-códigos | AO23: 0 | AQ23: 0 | AR23: 0 | AT23: 0 | AX23: Pendente
A24: 2022_BRAULIO_LARA_741_01 | B24: 2022 | C24: 4671 | D24: emendas_conslidadas(1).xlsx | E24: 2022_BRAULIO_LARA | F24: 741 | G24: Concluída | H24: Braulio Lara | I24: NOVO | J24: Ao reforço de dotação orçamentária para estudos, projetos e implantação de acessos e/ou outras benfeitorias no bairro Buritis, em especial, na Rua Elza Beatriz de Araújo, que interliga à Rua Tereza Mota Valadares com a Rua Maria Heilbuth Surette; Rua Márcio Maia Ferreira, que interliga à Av. Professor Mário Werneck com a Rua Eli Seabra Filho; e Rua VDP3981, que interliga a Rua Deputado Sebastião Nascimento com a Rua Deputado Fábio Vasconcelos; e estudos, projetos e implantação de pista de Skate na Praça Moisés Kalil, dentre outros; | K24: -2700.15.451.233.1208.449051 | L24: 2700 | M24: SECRETARIA MUNICIPAL DE OBRAS E INFRAESTRUTURA | N24: 15 | O24: Urbanismo | P24: 451 | Q24: Infra-Estrutura Urbana | R24: 0233 | S24: Manutenção da Cidade | T24: 1208 | U24: Conservação de Vias Urbanas | V24: 449051 | W24: Despesa de capital | X24: Investimentos | Z24: SMOBI | AA24: 1000000 | AB24: 584328.08 | AC24: 0 | AD24: 584328.08 | AE24: ESTRUTURA ENGENHARIA E CONSTRUCAO LTDA. ESTRUTURA ENGENHARIA E CONSTRUCAO LTDA. TECHVIAS ENGENHARIA LTDA | AF24: 19590967000107 19590967000107 11871903000164 | AG24: - | AH24: - | AI24: - | AJ24: 0 | AK24: 0 | AL24: 1403 | AM24: =IF(AL24="","",AL24&" - "&IFERROR(VLOOKUP(AL24,CODEBOOK_CAP!$C$2:$D$212,2,FALSE),"")) -> 1403 - REABILITAÇÃO URBANA, ECONOMIA URBANA | AN24: =IF(AL24="","",IFERROR(VLOOKUP(AL24,CODEBOOK_CAP!$C$2:$E$212,3,FALSE),"")) -> Reabilitação de áreas urbanas, revitalização urbana, modernização de áreas, mercados públicos, revitalização de praças, política urbana nacional, desenvolvimento urbano , desenvolvimento econômico de estados e cidades, modernização de espaços urbanos | AO24: 1 | AP24: Rua Elza Beatriz de Araújo, que interliga à Rua Tereza Mota Valadares com a Rua Maria Heilbuth Surette; Rua Márcio Maia Ferreira, que interliga à Av. Professor Mário Werneck com a Rua Eli Seabra Filho; e Rua VDP3981, que interliga a Rua Deputado Sebastião Nascimento com a Rua Deputado Fábio Vasconcelos; e estudos, projetos e implantação de pista de Skate na Praça Moisés Kalil, dentre outros; | AQ24: 4 | AR24: 1 | AS24: Rua Elza Beatriz de Araújo, que interliga à Rua Tereza Mota Valadares com a Rua Maria Heilbuth Surette; Rua Márcio Maia Ferreira, que interliga à Av. Professor Mário Werneck com a Rua Eli Seabra Filho; e Rua VDP3981, que interliga a Rua Deputado Sebastião Nascimento com a Rua Deputado Fábio Vasconcelos; e estudos, projetos e implantação de pista de Skate na Praça Moisés Kalil, dentre outros; | AT24: 0 | AX24: Pendente
A25: 2022_BRAULIO_LARA_742_01 | B25: 2022 | C25: 4672 | D25: emendas_conslidadas(1).xlsx | E25: 2022_BRAULIO_LARA | F25: 742 | G25: Concluída | H25: Braulio Lara | I25: NOVO | J25: Destinação de recursos para a Instituto Pedra Viva, CNPJ: 08.878.503/0001-76, para a execução de atividades socioassistenciais, de acordo com o disposto na Lei Federal nº 8.742/93, em consonância com a referida inscrição no Conselho Municipal de Assistência Social de Belo Horizonte – CMAS-BH; | K25: 1011.08.244.113.2804.339039 | L25: 1011 | M25: FUNDO MUNICIPAL DE ASSISTÊNCIA SOCIAL | N25: 08 | O25: Assistência Social | P25: 244 | Q25: Assistência Comunitária | R25: 0113 | S25: Aprimoramento da Gestão do SUAS | T25: 2804 | U25: Gestão dos Equipamentos e Promoção Social | V25: 339039 | W25: Despesa corrente | X25: Outras despesas correntes | Z25: SMASDH | AA25: 50000 | AB25: 50000 | AC25: 50000 | AD25: 50000 | AE25: INSTITUTO PEDRA VIVA | AF25: 08878503000176 | AG25: Associações Diversas | AH25: Associações Diversas | AJ25: 0 | AK25: 0 | AL25: 1300 | AM25: =IF(AL25="","",AL25&" - "&IFERROR(VLOOKUP(AL25,CODEBOOK_CAP!$C$2:$D$212,2,FALSE),"")) -> 1300 - GERAL | AN25: =IF(AL25="","",IFERROR(VLOOKUP(AL25,CODEBOOK_CAP!$C$2:$E$212,3,FALSE),"")) -> Observações gerais sobre políticas sociais que envolvam mais de um casos dos subtópicos, políticas gerais de assistência social, welfare state, bem estar social, Ministérios e orcamentos como do Desenvolvimento social e combate e fome, desenvolvimento social, sistemas de gestão de políticas de assistencia, CAD UNICO, cadastros, sistemas computacionais para desenvolvimento de ações e políticas sociais, BPC - Benefício de Prestação Continuada geral para idosos e deficientes. NÃO CONFUNDIR POLÍTICAS SOCIAIS COM POLÍTICA DE EMPREGO E RENDA. Todas as questões, direitos, políticas que se relacionem com o TRABALHO como contrapartida, estão no código 5. Maternidade, Paternidade aposentadoria por tempo de serviço, INSS. | AO25: 0 | AQ25: 0 | AR25: 0 | AT25: 0 | AX25: Pendente
A26: 2022_BRAULIO_LARA_743_01 | B26: 2022 | C26: 4673 | D26: emendas_conslidadas(1).xlsx | E26: 2022_BRAULIO_LARA | F26: 743 | G26: Cancelada | H26: Braulio Lara | I26: Novo | J26: Ao reforço de dotação orçamentária para complemento de obras da Rua VDP3981, conforme CP273009M, que interliga a Rua Deputado Sebastião Nascimento com a Rua Deputado Fábio Vasconcelos Plano de Obras 0505: L4-U- URB-11: Taquaril 1a Etapa; | K26: - | Z26: Cancelada | AA26: 300000 | AE26: - | AF26: - | AG26: - | AH26: - | AI26: - | AJ26: 0 | AK26: 0 | AL26: 1002 | AM26: =IF(AL26="","",AL26&" - "&IFERROR(VLOOKUP(AL26,CODEBOOK_CAP!$C$2:$D$212,2,FALSE),"")) -> 1002 - CARROS, TRÂNSITO, CONSTRUÇÃO E MANUTENÇÃO DE RUAS E ESTRADAS | AN26: =IF(AL26="","",IFERROR(VLOOKUP(AL26,CODEBOOK_CAP!$C$2:$E$212,3,FALSE),"")) -> Construção, manutenção de ruas, avenidas, estradas. BRs, pedágios, privatizações, concessinárias, segurança nas estradas, leis de trânsito relacionadas a via, limite de velocidade, sinalização, recapeamento de ruas, pavimentação estradas de terra, não pavimentadas, acidentes e camapanhas de prevencao contra acidentes de transito. Observações sobre regulação de transportes não públicos de carros, veículos de passeio, uber, taxi, transporte de cargas terrestre, frete, trânsito em vias públicas, regulamentação de tipos de carteira de motorista, especificações para caminhoneiros, testes e exames de habilitação, exigências de carteira de habilitação, obrigatoriedade de itens em veículos (extintor, kit primeiros socorros, airbag, freios abs) Quando tratar de grandes obras de construções de rodovias, olhar codigo 1010 para ver qual se encaixa melhor. | AO26: 1 | AP26: Rua VDP3981, conforme CP273009M, que interliga a Rua Deputado Sebastião Nascimento com a Rua Deputado Fábio Vasconcelos Plano de Obras 0505: L4-U- URB-11: Taquaril 1a Etapa; | AQ26: 1 | AR26: 1 | AS26: Rua VDP3981, conforme CP273009M, que interliga a Rua Deputado Sebastião Nascimento com a Rua Deputado Fábio Vasconcelos Plano de Obras 0505: L4-U- URB-11: Taquaril 1a Etapa; | AT26: 0 | AX26: Pendente
A27: 2022_BRAULIO_LARA_800_01 | B27: 2022 | C27: 4726 | D27: emendas_conslidadas(1).xlsx | E27: 2022_BRAULIO_LARA | F27: 800 | G27: Concluída | H27: Braulio Lara | I27: NOVO | J27: Ao reforço de dotação orçamentária destinada ao Centro de Saúde Havaí (R. Manila, 432 - Estrela Dalva, Belo Horizonte - MG, 30570-360), para contratação de serviços ligados a manutenções, melhorias e revitalização de instalações; | K27: 2302.10.301.157.2902.336783 | L27: 2302 | M27: FUNDO MUNICIPAL DE SAÚDE | N27: 10 | O27: Saúde | P27: 301 | Q27: Atenção Básica | R27: 0157 | S27: Atenção Primária à Saúde | T27: 2902 | U27: Gestão das Parcerias Público-Privadas | V27: 336783 | W27: Despesa corrente | X27: Outras despesas correntes | Z27: SMSA | AA27: 50000 | AB27: 50000 | AC27: 50000 | AD27: 50000 | AE27: SPE SAUDE PRIMARIA BH S/A | AF27: 23921007000141 | AG27: PBH | AH27: Município de Belo Horizonte | AI27: 18715383000140 | AJ27: 1 | AK27: 1 | AL27: 0322 | AM27: =IF(AL27="","",AL27&" - "&IFERROR(VLOOKUP(AL27,CODEBOOK_CAP!$C$2:$D$212,2,FALSE),"")) -> 0322 - ESTRUTURAS, HOSPITAIS, CLÍNICAS | AN27: =IF(AL27="","",IFERROR(VLOOKUP(AL27,CODEBOOK_CAP!$C$2:$E$212,3,FALSE),"")) -> Observações relacionadas as estruturas do sistema de saúde, como a construção de hospitais, postos de saúde, construção de maternidades, laboratórios, centros de saúde avançado, SAMU, Ambulâncias, UTI Móveis, leitos, compra de equipamentos médicos, Raio X, Ultrasom, equipamentos de diálise, capacidade de atendimento, estrutura e funcionamento de equipamentos públicos de saúde. | AO27: 1 | AP27: Centro de Saúde Havaí (R. Manila, 432 - Estrela Dalva, Belo Horizonte - MG, 30570-360) | AQ27: 1 | AR27: 1 | AS27: Centro de Saúde Havaí (R. Manila, 432 - Estrela Dalva, Belo Horizonte - MG, 30570-360) | AT27: 0 | AX27: Pendente
A28: 2022_BRAULIO_LARA_801_01 | B28: 2022 | C28: 4727 | D28: emendas_conslidadas(1).xlsx | E28: 2022_BRAULIO_LARA | F28: 801 | G28: Concluída | H28: Braulio Lara | I28: NOVO | J28: Ao reforço de dotação orçamentária destinada ao Centro de Saúde Palmeiras (Av. Dom João VI, 1821 - Palmeiras, Belo Horizonte - MG, 30575-460), para contratação de serviços ligados a manutenções, melhorias e revitalização de instalações; | K28: 2302.10.122.117.1216.449051 | L28: 2302 | M28: FUNDO MUNICIPAL DE SAÚDE | N28: 10 | O28: Saúde | P28: 122 | Q28: Administração Geral | R28: 0117 | S28: Gestão do SUS | T28: 1216 | U28: Construção, Ampliação e Reforma de Unidades de Saúde | V28: 449051 | W28: Despesa de capital | X28: Investimentos | Z28: SMSA | AA28: 50000 | AB28: 47505 | AC28: 47505 | AD28: 47505 | AE28: CONSTRUTORA CAMPOS E FILHOS LTDA. | AF28: 15862332000152 | AG28: PBH | AH28: Município de Belo Horizonte | AI28: 18715383000140 | AJ28: 1 | AK28: 1 | AL28: 0322 | AM28: =IF(AL28="","",AL28&" - "&IFERROR(VLOOKUP(AL28,CODEBOOK_CAP!$C$2:$D$212,2,FALSE),"")) -> 0322 - ESTRUTURAS, HOSPITAIS, CLÍNICAS | AN28: =IF(AL28="","",IFERROR(VLOOKUP(AL28,CODEBOOK_CAP!$C$2:$E$212,3,FALSE),"")) -> Observações relacionadas as estruturas do sistema de saúde, como a construção de hospitais, postos de saúde, construção de maternidades, laboratórios, centros de saúde avançado, SAMU, Ambulâncias, UTI Móveis, leitos, compra de equipamentos médicos, Raio X, Ultrasom, equipamentos de diálise, capacidade de atendimento, estrutura e funcionamento de equipamentos públicos de saúde. | AO28: 1 | AP28: Centro de Saúde Palmeiras (Av. Dom João VI, 1821 - Palmeiras, Belo Horizonte - MG, 30575-460) | AQ28: 1 | AR28: 1 | AS28: Centro de Saúde Palmeiras (Av. Dom João VI, 1821 - Palmeiras, Belo Horizonte - MG, 30575-460) | AT28: 0 | AX28: Pendente
A29: 2022_BRAULIO_LARA_802_01 | B29: 2022 | C29: 4728 | D29: emendas_conslidadas(1).xlsx | E29: 2022_BRAULIO_LARA | F29: 802 | G29: Concluída | H29: Braulio Lara | I29: NOVO | J29: Ao reforço de dotação orçamentária destinada ao Centro de Saúde Vila Leonina (Praça do Ensino, 240 - Alpes, Belo Horizonte - MG, 30421-484), para contratação de serviços ligados a manutenções, melhorias e revitalização de instalações; | K29: 2302.10.122.117.1216.449051 | L29: 2302 | M29: FUNDO MUNICIPAL DE SAÚDE | N29: 10 | O29: Saúde | P29: 122 | Q29: Administração Geral | R29: 0117 | S29: Gestão do SUS | T29: 1216 | U29: Construção, Ampliação e Reforma de Unidades de Saúde | V29: 449051 | W29: Despesa de capital | X29: Investimentos | Z29: SMSA | AA29: 50000 | AB29: 47499 | AC29: 47499 | AD29: 47499 | AE29: MAUMA ENGENHARIA E SERVICOS LTDA. | AF29: 02496187000191 | AG29: PBH | AH29: Município de Belo Horizonte | AI29: 18715383000140 | AJ29: 1 | AK29: 1 | AL29: 0322 | AM29: =IF(AL29="","",AL29&" - "&IFERROR(VLOOKUP(AL29,CODEBOOK_CAP!$C$2:$D$212,2,FALSE),"")) -> 0322 - ESTRUTURAS, HOSPITAIS, CLÍNICAS | AN29: =IF(AL29="","",IFERROR(VLOOKUP(AL29,CODEBOOK_CAP!$C$2:$E$212,3,FALSE),"")) -> Observações relacionadas as estruturas do sistema de saúde, como a construção de hospitais, postos de saúde, construção de maternidades, laboratórios, centros de saúde avançado, SAMU, Ambulâncias, UTI Móveis, leitos, compra de equipamentos médicos, Raio X, Ultrasom, equipamentos de diálise, capacidade de atendimento, estrutura e funcionamento de equipamentos públicos de saúde. | AO29: 1 | AP29: Centro de Saúde Vila Leonina (Praça do Ensino, 240 - Alpes, Belo Horizonte - MG, 30421-484) | AQ29: 1 | AR29: 1 | AS29: Centro de Saúde Vila Leonina (Praça do Ensino, 240 - Alpes, Belo Horizonte - MG, 30421-484) | AT29: 0 | AX29: Pendente
A30: 2022_BRAULIO_LARA_803_01 | B30: 2022 | C30: 4729 | D30: emendas_conslidadas(1).xlsx | E30: 2022_BRAULIO_LARA | F30: 803 | G30: Concluída | H30: Braulio Lara | I30: NOVO | J30: Ao reforço de dotação orçamentária destinada ao Centro de Saúde Salgado Filho (R. Campína Verde, 375 - Salgado Filho, Belo Horizonte - MG, 30550-340), para contratação de serviços ligados a manutenções, melhorias e revitalização de instalações; | K30: 2302.10.122.117.1216.449051 | L30: 2302 | M30: FUNDO MUNICIPAL DE SAÚDE | N30: 10 | O30: Saúde | P30: 122 | Q30: Administração Geral | R30: 0117 | S30: Gestão do SUS | T30: 1216 | U30: Construção, Ampliação e Reforma de Unidades de Saúde | V30: 449051 | W30: Despesa de capital | X30: Investimentos | Z30: SMSA | AA30: 50000 | AB30: 43924 | AC30: 43924 | AD30: 43924 | AE30: CONSTRUTORA CAMPOS E FILHOS LTDA. | AF30: 15862332000152 | AG30: PBH | AH30: Município de Belo Horizonte | AI30: 18715383000140 | AJ30: 1 | AK30: 1 | AL30: 0322 | AM30: =IF(AL30="","",AL30&" - "&IFERROR(VLOOKUP(AL30,CODEBOOK_CAP!$C$2:$D$212,2,FALSE),"")) -> 0322 - ESTRUTURAS, HOSPITAIS, CLÍNICAS | AN30: =IF(AL30="","",IFERROR(VLOOKUP(AL30,CODEBOOK_CAP!$C$2:$E$212,3,FALSE),"")) -> Observações relacionadas as estruturas do sistema de saúde, como a construção de hospitais, postos de saúde, construção de maternidades, laboratórios, centros de saúde avançado, SAMU, Ambulâncias, UTI Móveis, leitos, compra de equipamentos médicos, Raio X, Ultrasom, equipamentos de diálise, capacidade de atendimento, estrutura e funcionamento de equipamentos públicos de saúde. | AO30: 1 | AP30: Centro de Saúde Salgado Filho (R. Campína Verde, 375 - Salgado Filho, Belo Horizonte - MG, 30550-340) | AQ30: 1 | AR30: 1 | AS30: Centro de Saúde Salgado Filho (R. Campína Verde, 375 - Salgado Filho, Belo Horizonte - MG, 30550-340) | AT30: 0 | AX30: Pendente
A31: 2022_BRAULIO_LARA_804_01 | B31: 2022 | C31: 4730 | D31: emendas_conslidadas(1).xlsx | E31: 2022_BRAULIO_LARA | F31: 804 | G31: Concluída | H31: Braulio Lara | I31: NOVO | J31: Ao reforço de dotação orçamentária destinada ao Centro de Saúde Betânia, para realização de manutenções, melhorias e revitalização de instalações; | K31: 2302.10.122.117.1216.449051 | L31: 2302 | M31: FUNDO MUNICIPAL DE SAÚDE | N31: 10 | O31: Saúde | P31: 122 | Q31: Administração Geral | R31: 0117 | S31: Gestão do SUS | T31: 1216 | U31: Construção, Ampliação e Reforma de Unidades de Saúde | V31: 449051 | W31: Despesa de capital | X31: Investimentos | Z31: SMSA | AA31: 50000 | AB31: 33672 | AC31: 33672 | AD31: 33672 | AE31: MAUMA ENGENHARIA E SERVICOS LTDA. | AF31: 02496187000191 | AG31: PBH | AH31: Município de Belo Horizonte | AI31: 18715383000140 | AJ31: 1 | AK31: 1 | AL31: 0322 | AM31: =IF(AL31="","",AL31&" - "&IFERROR(VLOOKUP(AL31,CODEBOOK_CAP!$C$2:$D$212,2,FALSE),"")) -> 0322 - ESTRUTURAS, HOSPITAIS, CLÍNICAS | AN31: =IF(AL31="","",IFERROR(VLOOKUP(AL31,CODEBOOK_CAP!$C$2:$E$212,3,FALSE),"")) -> Observações relacionadas as estruturas do sistema de saúde, como a construção de hospitais, postos de saúde, construção de maternidades, laboratórios, centros de saúde avançado, SAMU, Ambulâncias, UTI Móveis, leitos, compra de equipamentos médicos, Raio X, Ultrasom, equipamentos de diálise, capacidade de atendimento, estrutura e funcionamento de equipamentos públicos de saúde. | AO31: 1 | AP31: Centro de Saúde Betânia | AQ31: 1 | AR31: 1 | AS31: Centro de Saúde Betânia | AT31: 0 | AX31: Pendente
A32: 2022_BRAULIO_LARA_805_01 | B32: 2022 | C32: 4731 | D32: emendas_conslidadas(1).xlsx | E32: 2022_BRAULIO_LARA | F32: 805 | G32: Concluída | H32: Braulio Lara | I32: NOVO | J32: Ao reforço de dotação orçamentária destinada ao Centro de Saúde de Amilcar Vianna Martins (R. Nelson de Senna, 90 - Cinquentenário, Belo Horizonte - MG, 30570-060), para contratação de serviços ligados a manutenções, melhorias e revitalização de instalações; | K32: 2302.10.122.117.1216.449051 | L32: 2302 | M32: FUNDO MUNICIPAL DE SAÚDE | N32: 10 | O32: Saúde | P32: 122 | Q32: Administração Geral | R32: 0117 | S32: Gestão do SUS | T32: 1216 | U32: Construção, Ampliação e Reforma de Unidades de Saúde | V32: 449051 | W32: Despesa de capital | X32: Investimentos | Z32: SMSA | AA32: 50000 | AB32: 49814 | AC32: 49814 | AD32: 49814 | AE32: MAUMA ENGENHARIA E SERVICOS LTDA. MAUMA ENGENHARIA E SERVICOS LTDA. | AF32: 02496187000191 02496187000191 | AG32: PBH | AH32: Município de Belo Horizonte | AI32: 18715383000140 | AJ32: 1 | AK32: 1 | AL32: 0322 | AM32: =IF(AL32="","",AL32&" - "&IFERROR(VLOOKUP(AL32,CODEBOOK_CAP!$C$2:$D$212,2,FALSE),"")) -> 0322 - ESTRUTURAS, HOSPITAIS, CLÍNICAS | AN32: =IF(AL32="","",IFERROR(VLOOKUP(AL32,CODEBOOK_CAP!$C$2:$E$212,3,FALSE),"")) -> Observações relacionadas as estruturas do sistema de saúde, como a construção de hospitais, postos de saúde, construção de maternidades, laboratórios, centros de saúde avançado, SAMU, Ambulâncias, UTI Móveis, leitos, compra de equipamentos médicos, Raio X, Ultrasom, equipamentos de diálise, capacidade de atendimento, estrutura e funcionamento de equipamentos públicos de saúde. | AO32: 1 | AP32: Centro de Saúde de Amilcar Vianna Martins (R. Nelson de Senna, 90 - Cinquentenário, Belo Horizonte - MG, 30570-060) | AQ32: 1 | AR32: 1 | AS32: Centro de Saúde de Amilcar Vianna Martins (R. Nelson de Senna, 90 - Cinquentenário, Belo Horizonte - MG, 30570-060) | AT32: 0 | AX32: Pendente
A33: 2022_BRAULIO_LARA_806_01 | B33: 2022 | C33: 4732 | D33: emendas_conslidadas(1).xlsx | E33: 2022_BRAULIO_LARA | F33: 806 | G33: Concluída | H33: Braulio Lara | I33: NOVO | J33: Ao reforço de dotação orçamentária destinada ao Centro de Saúde Vila Imperial (Rua Guilherme Pinto da Fonseca, 350 - Me. Gertrudes, Belo Horizonte - MG, 30518-240), para contratação de serviços ligados a manutenções, melhorias e revitalização de instalações; | K33: 2302.10.122.117.1216.449051 | L33: 2302 | M33: FUNDO MUNICIPAL DE SAÚDE | N33: 10 | O33: Saúde | P33: 122 | Q33: Administração Geral | R33: 0117 | S33: Gestão do SUS | T33: 1216 | U33: Construção, Ampliação e Reforma de Unidades de Saúde | V33: 449051 | W33: Despesa de capital | X33: Investimentos | Z33: SMSA | AA33: 50000 | AB33: 50000 | AC33: 50000 | AD33: 50000 | AE33: MAUMA ENGENHARIA E SERVICOS LTDA. | AF33: 02496187000191 | AG33: PBH | AH33: Município de Belo Horizonte | AI33: 18715383000140 | AJ33: 1 | AK33: 1 | AL33: 0322 | AM33: =IF(AL33="","",AL33&" - "&IFERROR(VLOOKUP(AL33,CODEBOOK_CAP!$C$2:$D$212,2,FALSE),"")) -> 0322 - ESTRUTURAS, HOSPITAIS, CLÍNICAS | AN33: =IF(AL33="","",IFERROR(VLOOKUP(AL33,CODEBOOK_CAP!$C$2:$E$212,3,FALSE),"")) -> Observações relacionadas as estruturas do sistema de saúde, como a construção de hospitais, postos de saúde, construção de maternidades, laboratórios, centros de saúde avançado, SAMU, Ambulâncias, UTI Móveis, leitos, compra de equipamentos médicos, Raio X, Ultrasom, equipamentos de diálise, capacidade de atendimento, estrutura e funcionamento de equipamentos públicos de saúde. | AO33: 1 | AP33: Centro de Saúde Vila Imperial (Rua Guilherme Pinto da Fonseca, 350 - Me. Gertrudes, Belo Horizonte - MG, 30518-240) | AQ33: 1 | AR33: 1 | AS33: Centro de Saúde Vila Imperial (Rua Guilherme Pinto da Fonseca, 350 - Me. Gertrudes, Belo Horizonte - MG, 30518-240) | AT33: 0 | AX33: Pendente
