Workbook

Sheet EMENDAS_CODIFICACAO
A1: id_emenda | B1: ano | C1: linha_origem | D1: arquivo_origem | E1: id_vereador_ano | F1: numero_emenda | G1: status_original | H1: parlamentar_original | I1: partido_base | J1: objeto_emenda | K1: dotacao_original | L1: uo_dec | M1: nome_uo | N1: func_dec | O1: nome_funcao | P1: sub_dec | Q1: nome_subfuncao | R1: prog_dec | S1: nome_programa | T1: acao_dec | U1: nome_acao | V1: nat_dec | W1: categoria_economica | X1: grupo_despesa | Y1: fonte_dec | Z1: orgao_executor | AA1: valor_emenda | AB1: valor_empenhado | AC1: valor_liquidado | AD1: valor_pago | AE1: credor_original | AF1: saude_orcamentaria | AG1: saude_tematica | AH1: subcodigo_cap_final | AI1: subcodigo_cap | AJ1: subcodigo_cap_descricao | AK1: localidade_final | AL1: localidade_resumo | AM1: N_localidades | AN1: georreferenciavel | AO1: georreferenciacao | AP1: publico_alvo_final | AQ1: publico_alvo_resumo | AR1: credor_disponivel_final | AS1: credor_padronizado | AT1: status_codificacao | AU1: confianca | AV1: data_codificacao | AW1: regra_decisao_id | AX1: cultura_ou_esporte
A2: 2023_BELLA_GONCALVES_566_01 | B2: 2023 | C2: 358 | D2: emendas-2023-27-11-2025.xlsx | E2: 2023_BELLA_GONCALVES | F2: 566 | G2: ATOS PREPARATÓRIOS | H2: Bella Gonçalves | J2: à reforma dos Centros de Referência em Saúde Mental Noroeste (CERSAM Noroeste), Centros de Referência em Saúde Mental Infanto-Juvenil Noroeste (CERSAMi Noroeste) e Centros de Referência em Saúde Mental Infanto-Juvenil Centro-Sul (CERSAMi Centro-Sul/CEPAI) | K2: 2302.1012201171.216.449051.S.500 | L2: 2302 | M2: FUNDO MUNICIPAL DE SAÚDE | N2: 10 | O2: SAÚDE | P2: 122 | Q2: ADMINISTRAÇÃO GERAL | R2: 0117 | S2: GESTÃO DO SUS | T2: 1216 | U2: CONSTRUÇÃO, AMPLIAÇÃO E REFORMA DE UNIDADES DE SAÚDE | V2: 449051 | W2: Despesa de capital | X2: Investimentos | Y2: 500 | Z2: FMS/SMOBI | AA2: 1223854 | AB2: 813820.27 | AC2: 803820.27 | AD2: 803820.27 | AE2: VALESK CONSTRUCOES LTDA, | AF2: 1 | AG2: 1 | AH2: 0333 | AI2: =IF(AH2="","",IFERROR(RIGHT("0000"&AH2,4)&" - "&UPPER(_xlfn.XLOOKUP(RIGHT("0000"&AH2,4),CODEBOOK_CAP!$C$2:$C$212,CODEBOOK_CAP!$D$2:$D$212)),"Código CAP não encontrado")) -> 0333 - SAÚDE MENTAL | AJ2: =IF(AH2="","",IFERROR(_xlfn.XLOOKUP(RIGHT("0000"&AH2,4),CODEBOOK_CAP!$C$2:$C$212,CODEBOOK_CAP!$E$2:$E$212),"Código CAP não encontrado")) -> Serviços de atendimento a saúde mental e psico-social. CAPS, Controle de qualidade mental, esquizofrenia, bipolaridade, transtornos mentais, ansiedade, alucinançao, depressão, suicídio, CVV, atendimento psicológico e psiquiátrico, sanatório, manicomio. Não confundir com dependências de alcool (342) e drogas (343) | AK2: 0 | AM2: 3 | AN2: 1 | AO2: R. Camarugi, 10 - Padre Eustáquio, Belo Horizonte - MG, 30720-090; R. Manhumirim, 415 - Padre Eustáquio, Belo Horizonte - MG, 30720-070; R. Padre Marinho, 150 - Santa Efigênia, Belo Horizonte - MG, 30140-040 | AP2: 1 | AQ2: Infanto-Juvenil | AR2: 1 | AS2: VALESK CONSTRUCOES LTDA, | AT2: Revisado | AU2: Alta | AV2: 46214
A3: 2023_BELLA_GONCALVES_569_01 | B3: 2023 | C3: 361 | D3: emendas-2023-27-11-2025.xlsx | E3: 2023_BELLA_GONCALVES | F3: 569 | G3: CONCLUÍDO | H3: Bella Gonçalves | J3: à realização de eventos de formação com foco no público usuário dos serviços de saúde mental | K3: 2302.1030201142.891.339039.S.500 | L3: 2302 | M3: FUNDO MUNICIPAL DE SAÚDE | N3: 10 | O3: SAÚDE | P3: 302 | Q3: ASSISTÊNCIA HOSPITALAR E AMBULATORIAL | R3: 0114 | S3: ATENÇÃO SECUNDÁRIA E TERCIÁRIA À SAÚDE | T3: 2891 | U3: REDE ESPECIALIZADA | V3: 339039 | W3: Despesa corrente | X3: Outras despesas correntes | Y3: 500 | Z3: FMS | AA3: 104100 | AB3: 104100 | AC3: 104100 | AD3: 104100 | AF3: 1 | AG3: 1 | AH3: 0333 | AI3: =IF(AH3="","",IFERROR(RIGHT("0000"&AH3,4)&" - "&UPPER(_xlfn.XLOOKUP(RIGHT("0000"&AH3,4),CODEBOOK_CAP!$C$2:$C$212,CODEBOOK_CAP!$D$2:$D$212)),"Código CAP não encontrado")) -> 0333 - SAÚDE MENTAL | AJ3: =IF(AH3="","",IFERROR(_xlfn.XLOOKUP(RIGHT("0000"&AH3,4),CODEBOOK_CAP!$C$2:$C$212,CODEBOOK_CAP!$E$2:$E$212),"Código CAP não encontrado")) -> Serviços de atendimento a saúde mental e psico-social. CAPS, Controle de qualidade mental, esquizofrenia, bipolaridade, transtornos mentais, ansiedade, alucinançao, depressão, suicídio, CVV, atendimento psicológico e psiquiátrico, sanatório, manicomio. Não confundir com dependências de alcool (342) e drogas (343) | AK3: 0 | AM3: 0 | AN3: 0 | AP3: 0 | AR3: 0 | AT3: Revisado | AU3: Alta | AV3: 46214
A4: 2023_BELLA_GONCALVES_571_01 | B4: 2023 | C4: 363 | D4: emendas-2023-27-11-2025.xlsx | E4: 2023_BELLA_GONCALVES | F4: 571 | G4: CONCLUÍDO | H4: Bella Gonçalves | J4: à aquisição de material de apoio utilizado no atendimento das Equipes de Consultório na Rua. | K4: 2302.1030201142.891.335043.S.500 | L4: 2302 | M4: FUNDO MUNICIPAL DE SAÚDE | N4: 10 | O4: SAÚDE | P4: 302 | Q4: ASSISTÊNCIA HOSPITALAR E AMBULATORIAL | R4: 0114 | S4: ATENÇÃO SECUNDÁRIA E TERCIÁRIA À SAÚDE | T4: 2891 | U4: REDE ESPECIALIZADA | V4: 335043 | W4: Despesa corrente | X4: Outras despesas correntes | Y4: 500 | Z4: FMS | AA4: 112578 | AB4: 112578 | AC4: 112578 | AD4: 112578 | AF4: 1 | AG4: 1 | AH4: 0304 | AI4: =IF(AH4="","",IFERROR(RIGHT("0000"&AH4,4)&" - "&UPPER(_xlfn.XLOOKUP(RIGHT("0000"&AH4,4),CODEBOOK_CAP!$C$2:$C$212,CODEBOOK_CAP!$D$2:$D$212)),"Código CAP não encontrado")) -> 0304 - CUIDADOS PRIMARIOS E ATENÇÃO BÁSICA | AJ4: =IF(AH4="","",IFERROR(_xlfn.XLOOKUP(RIGHT("0000"&AH4,4),CODEBOOK_CAP!$C$2:$C$212,CODEBOOK_CAP!$E$2:$E$212),"Código CAP não encontrado")) -> Medicina da familia, cuidados básicos e informativos de saude, higiene pessoal e higiene alimentar. Normalmente vinculada a comunidades carentes e de exercício de práticas gerenciais e sanitárias democráticas, atuacao de trabalho em equipe, dirigidas a populações de territórios bem delimitados, pelas quais assume a responsabilidade sanitária, considerando a dinamicidade existente no território em que vivem essas populações. Programa saúde da família, Política Nacional de atenção básica, Equipes de Saúde da Família, Agentes comunitários de saúde. Mias médicos quando se tratar de inclusão regional, interiorização do atendimento. Quando tratar apenas de prevenção e promoção a saude, como campanhas específicas contra dengue, DSTs, codificar em (331) | AK4: 0 | AM4: 0 | AN4: 0 | AP4: 0 | AR4: 0 | AT4: Revisado | AU4: Alta | AV4: 46214
A5: 2023_BELLA_GONCALVES_574_01 | B5: 2023 | C5: 366 | D5: emendas-2023-27-11-2025.xlsx | E5: 2023_BELLA_GONCALVES | F5: 574 | G5: CONCLUÍDO | H5: Bella Gonçalves | J5: ao reforço de dotação orçamentária para qualificação no atendimento da população LGBT através do "Projeto BH de Mão Dadas Contra a Aids". | K5: 2302.1030500282.829.335043.S.500 | L5: 2302 | M5: FUNDO MUNICIPAL DE SAÚDE | N5: 10 | O5: SAÚDE | P5: 305 | Q5: VIGILÂNCIA EPIDEMIOLÓGICA | R5: 0028 | S5: VIGILÂNCIA EM SAÚDE | T5: 2829 | U5: VIGILÂNCIA EM SAÚDE | V5: 335043 | W5: Despesa corrente | X5: Outras despesas correntes | Y5: 500 | Z5: FMS | AA5: 72000 | AB5: 72000 | AC5: 72000 | AD5: 72000 | AF5: 1 | AG5: 1 | AH5: 0331 | AI5: =IF(AH5="","",IFERROR(RIGHT("0000"&AH5,4)&" - "&UPPER(_xlfn.XLOOKUP(RIGHT("0000"&AH5,4),CODEBOOK_CAP!$C$2:$C$212,CODEBOOK_CAP!$D$2:$D$212)),"Código CAP não encontrado")) -> 0331 - PREVENÇÃO, CAMPANHAS E PROMOÇÃO | AJ5: =IF(AH5="","",IFERROR(_xlfn.XLOOKUP(RIGHT("0000"&AH5,4),CODEBOOK_CAP!$C$2:$C$212,CODEBOOK_CAP!$E$2:$E$212),"Código CAP não encontrado")) -> Observações relacionadas a campanhas de promoção e de prevenção de saúde em adultos. Campanhas de vacinação de adultos, campanhas de prevenção de DSTs em adultos, campanhas para exames de câncer de mama, outubro rosa, Novembro azul, campanhas de valorização da vida, campanhas contra suicídio, Políticas de prevenção a diabetes, campanhas e politicas em pro de atividades esportivas para evitar problemas de pressão, publicacao de cartilhas, guias, informativos, educação sexual, campanhas e atuação de higiene bucal, higiene básica, prevenção contra anemia. Não confundir com acesso a alimentos (1302), pre-natal (332) ou tratamentos de doenças já existentes. Todas campanhas de prevenção que estejam relacionadas com gravidez, bebê e criança (332), | AK5: 0 | AM5: 0 | AN5: 0 | AP5: 1 | AQ5: LGBT | AR5: 0 | AT5: Revisado | AU5: Alta | AV5: 46214
A6: 2023_BELLA_GONCALVES_580_01 | B6: 2023 | C6: 372 | D6: emendas-2023-27-11-2025.xlsx | E6: 2023_BELLA_GONCALVES | F6: 580 | G6: CONCLUÍDO | H6: Bella Gonçalves | J6: ao reforço de dotação orçamentária para o Hospital Eduardo de Menezes, CNPJ 19.843.929/0011- 82, para a compra de hormônios e outras medicações utilizadas no ambulatório Anyky Lima. | K6: 2302.1030201142.894.339039.S.500 | L6: 2302 | M6: FUNDO MUNICIPAL DE SAÚDE | N6: 10 | O6: SAÚDE | P6: 302 | Q6: ASSISTÊNCIA HOSPITALAR E AMBULATORIAL | R6: 0114 | S6: ATENÇÃO SECUNDÁRIA E TERCIÁRIA À SAÚDE | T6: 2894 | U6: REDE HOSPITALAR | V6: 339039 | W6: Despesa corrente | X6: Outras despesas correntes | Y6: 500 | Z6: FMS | AA6: 100000 | AB6: 100000 | AC6: 100000 | AD6: 100000 | AF6: 1 | AG6: 1 | AH6: 0335 | AI6: =IF(AH6="","",IFERROR(RIGHT("0000"&AH6,4)&" - "&UPPER(_xlfn.XLOOKUP(RIGHT("0000"&AH6,4),CODEBOOK_CAP!$C$2:$C$212,CODEBOOK_CAP!$D$2:$D$212)),"Código CAP não encontrado")) -> 0335 - REGULAMENTAÇÃO DE FARMÁCIAS , COMPRA E CONSUMO DE MEDICAMENTOS | AJ6: =IF(AH6="","",IFERROR(_xlfn.XLOOKUP(RIGHT("0000"&AH6,4),CODEBOOK_CAP!$C$2:$C$212,CODEBOOK_CAP!$E$2:$E$212),"Código CAP não encontrado")) -> Assuntos relacionados a compra e venda de medicamentos em farmácias. Regulamentação de horário de funcionamento de farmácias, farmácia popular, farmácias de manipulação, organização e regras para funcionamento de farmácias, proibição de atendimento médico em farmácias, controle de receitas, acesso a compra de medicamentos de tarja vermelha e tarja preta. Preço de medicamentos e remedios. Distribuição de medicamentos gratuitos. Questões relacionadas sobre patentes de medicamentos no 1522. Não confundir com assuntos relacionados a Industria Farmaceutica (321) | AK6: 0 | AM6: 1 | AN6: 1 | AO6: R. Dr. Cristiano Rezende, 2213 - Bonsucesso, Belo Horizonte - MG, 30622-020 | AP6: 1 | AQ6: LGBT; trans e travestis | AR6: 0 | AT6: Revisado | AU6: Alta | AV6: 46214
A7: 2023_BELLA_GONCALVES_585_01 | B7: 2023 | C7: 377 | D7: emendas-2023-27-11-2025.xlsx | E7: 2023_BELLA_GONCALVES | F7: 585 | G7: CONCLUÍDO | H7: Bella Gonçalves | J7: à implantação e estruturação do projeto Cozinha-Escola para realização de atividades de formação, oficinas, e cursos, com foco na geração de trabalho, emprego e renda, destinados a público em situação de vulnerabilidade social e comunidades em situação de insegurança alimentar | K7: 2800.0412202172.853.339039.F.500 | L7: 2800 | M7: SECRETARIA MUNICIPAL DE DESENVOLVIMENTO ECONÔMICO | N7: 04 | O7: ADMINISTRAÇÃO | P7: 122 | Q7: ADMINISTRAÇÃO GERAL | R7: 0217 | S7: FOMENTO AO DESENVOLVIMENTO ECONÔMICO | T7: 2853 | U7: PROMOÇÃO E ATRAÇÃO DE INVESTIMENTOS E EMPREENDEDORISMO | V7: 339039 | W7: Despesa corrente | X7: Outras despesas correntes | Y7: 500 | Z7: SMDE | AA7: 600000 | AB7: 600000 | AC7: 600000 | AD7: 600000 | AF7: 0 | AG7: 0 | AH7: 0502 | AI7: =IF(AH7="","",IFERROR(RIGHT("0000"&AH7,4)&" - "&UPPER(_xlfn.XLOOKUP(RIGHT("0000"&AH7,4),CODEBOOK_CAP!$C$2:$C$212,CODEBOOK_CAP!$D$2:$D$212)),"Código CAP não encontrado")) -> 0502 - FORMAÇÃO E DESENVOLVIMENTO PROFISSIONAL | AJ7: =IF(AH7="","",IFERROR(_xlfn.XLOOKUP(RIGHT("0000"&AH7,4),CODEBOOK_CAP!$C$2:$C$212,CODEBOOK_CAP!$E$2:$E$212),"Código CAP não encontrado")) -> Programas de capacitação profissional, programas de incentivo ao emprego geral, reciclagem, realocação profissional em outra área, acordos e parcerias do estado com empresas privadas na capacitação, formação e treinamento profissional. | AK7: 0 | AM7: 0 | AN7: 0 | AP7: 0 | AR7: 0 | AT7: Revisado | AU7: Alta | AV7: 46214
A8: 2023_BELLA_GONCALVES_601_01 | B8: 2023 | C8: 393 | D8: emendas-2023-27-11-2025.xlsx | E8: 2023_BELLA_GONCALVES | F8: 601 | G8: CONCLUÍDO | H8: Bella Gonçalves | J8: ao reforço de dotação orçamentária da política municipal_ "Cultura Viva"_. | K8: 3100.1339201542.930.339036.F.500 | L8: 3100 | M8: SECRETARIA MUNICIPAL DE CULTURA | N8: 13 | O8: CULTURA | P8: 392 | Q8: DIFUSÃO CULTURAL | R8: 0154 | S8: PROMOÇÃO E ACESSO ÀS ARTES E À CULTURA | T8: 2930 | U8: PROMOÇÃO E DEMOCRATIZAÇÃO DO ACESSO À CULTURA | V8: 339036 | W8: Despesa corrente | X8: Outras despesas correntes | Y8: 500 | Z8: SMC | AA8: 300000 | AB8: 300000 | AC8: 300000 | AD8: 300000 | AF8: 0 | AG8: 0 | AH8: 2300 | AI8: =IF(AH8="","",IFERROR(RIGHT("0000"&AH8,4)&" - "&UPPER(_xlfn.XLOOKUP(RIGHT("0000"&AH8,4),CODEBOOK_CAP!$C$2:$C$212,CODEBOOK_CAP!$D$2:$D$212)),"Código CAP não encontrado")) -> 2300 - GERAL | AJ8: =IF(AH8="","",IFERROR(_xlfn.XLOOKUP(RIGHT("0000"&AH8,4),CODEBOOK_CAP!$C$2:$C$212,CODEBOOK_CAP!$E$2:$E$212),"Código CAP não encontrado")) -> Observações relativas as políticas de cultura, Lei rouanet, patrimônio cultural, imaterial, políticas de artes, incentivos fiscais para artes, promoção de eventos culturais, amostras, teatro, dança, artes plásticas, artes visuais, museus, galerias públicas, idioma, lingua portuguesa. Grandes eventos esportivos, Copa do Mundo, Olimpiadas, Esporte e Lazer. | AK8: 0 | AM8: 0 | AN8: 0 | AP8: 0 | AR8: 0 | AT8: Revisado | AU8: Alta | AV8: 46214 | AX8: cultura
A9: 2023_BELLA_GONCALVES_607_01 | B9: 2023 | C9: 399 | D9: emendas-2023-27-11-2025.xlsx | E9: 2023_BELLA_GONCALVES | F9: 607 | G9: CONCLUÍDO | H9: Bella Gonçalves | J9: ao atendimento das mulheres em situação de violência identificadas nos termos da Lei n° 11.166/2019 (Lei da Morada Segura) | K9: 2704.1648202262.792.339048.F.500 | L9: 2704 | M9: FUNDO MUNICIPAL DE HABITAÇÃO POPULAR | N9: 16 | O9: HABITAÇÃO | P9: 482 | Q9: HABITAÇÃO URBANA | R9: 0226 | S9: PROVISÃO HABITACIONAL | T9: 2792 | U9: BOLSA MORADIA / LOCAÇÃO SOCIAL | V9: 339048 | W9: Despesa corrente | X9: Outras despesas correntes | Y9: 500 | Z9: SMOBI | AA9: 300000 | AB9: 114779.32 | AC9: 114779.32 | AD9: 114779.32 | AF9: 0 | AG9: 0 | AH9: 1406 | AI9: =IF(AH9="","",IFERROR(RIGHT("0000"&AH9,4)&" - "&UPPER(_xlfn.XLOOKUP(RIGHT("0000"&AH9,4),CODEBOOK_CAP!$C$2:$C$212,CODEBOOK_CAP!$D$2:$D$212)),"Código CAP não encontrado")) -> 1406 - POLÍTICAS DE HABITAÇÃO SOCIAL | AJ9: =IF(AH9="","",IFERROR(_xlfn.XLOOKUP(RIGHT("0000"&AH9,4),CODEBOOK_CAP!$C$2:$C$212,CODEBOOK_CAP!$E$2:$E$212),"Código CAP não encontrado")) -> Políticas de habitação para classes sociais específicas. Minha Casa Minha Vida, Cingapura, COHAB, atuação direta governamental em subsídios ou mesmo em construção de mutirões, doação de casas, prédios não utilizados e cedidos pelos governos. Assuntos relacionados a Favelas, comunidades. Inclui questões relacionadas à habitação para veteranos militares e suas famílias, incluindo | AK9: 0 | AM9: 0 | AN9: 0 | AP9: 1 | AQ9: mulheres | AR9: 0 | AT9: Revisado | AU9: Alta | AV9: 46214
A10: 2023_BELLA_GONCALVES_619_01 | B10: 2023 | C10: 411 | D10: emendas-2023-27-11-2025.xlsx | E10: 2023_BELLA_GONCALVES | F10: 619 | G10: IMPEDIMENTO TÉCNICO | H10: Bella Gonçalves | J10: à implantação e/ou manutenção de equipamento de infraestrutura esportiva e de lazer em estrutura pública municipal | K10: 3000.2781201012.534.449052.F.500 3000.2781201012.534.339039.F.500 | L10: 3000 | M10: SECRETARIA MUNICIPAL DE ESPORTES E LAZER | N10: 27 | O10: DESPORTO E LAZER | P10: 812 | Q10: DESPORTO COMUNITÁRIO | R10: 0101 | S10: PROMOÇÃO E DEMOCRATIZAÇÃO DAS PRÁTICAS DE ESPORTES E LAZER | T10: 2534 | U10: IMPLANTAÇÃO, MANUTENÇÃO E RECUPERAÇAO DE INFRAESTRUTURA ESPORTIVA E DE LAZER | V10: 449052 | W10: Despesa de capital | X10: Investimentos | Y10: 500 | Z10: SMEL | AA10: 150000 | AB10: 0 | AC10: 0 | AD10: 0 | AF10: 0 | AG10: 0 | AH10: 2300 | AI10: =IF(AH10="","",IFERROR(RIGHT("0000"&AH10,4)&" - "&UPPER(_xlfn.XLOOKUP(RIGHT("0000"&AH10,4),CODEBOOK_CAP!$C$2:$C$212,CODEBOOK_CAP!$D$2:$D$212)),"Código CAP não encontrado")) -> 2300 - GERAL | AJ10: =IF(AH10="","",IFERROR(_xlfn.XLOOKUP(RIGHT("0000"&AH10,4),CODEBOOK_CAP!$C$2:$C$212,CODEBOOK_CAP!$E$2:$E$212),"Código CAP não encontrado")) -> Observações relativas as políticas de cultura, Lei rouanet, patrimônio cultural, imaterial, políticas de artes, incentivos fiscais para artes, promoção de eventos culturais, amostras, teatro, dança, artes plásticas, artes visuais, museus, galerias públicas, idioma, lingua portuguesa. Grandes eventos esportivos, Copa do Mundo, Olimpiadas, Esporte e Lazer. | AK10: 0 | AM10: 0 | AN10: 0 | AP10: 0 | AR10: 0 | AT10: Revisado | AU10: Alta | AV10: 46214 | AX10: esporte e lazer
A11: 2023_BELLA_GONCALVES_622_01 | B11: 2023 | C11: 414 | D11: emendas-2023-27-11-2025.xlsx | E11: 2023_BELLA_GONCALVES | F11: 622 | G11: CONCLUÍDO | H11: Bella Gonçalves | J11: ao reforço de dotação orçamentária para continuidade de projeto de capacitação profissionalizante e empreendedorismo voltado às comunidades quilombolas no contexto urbano de Belo Horizonte. | K11: 2800.0412202172.853.339039.F.500 | L11: 2800 | M11: SECRETARIA MUNICIPAL DE DESENVOLVIMENTO ECONÔMICO | N11: 04 | O11: ADMINISTRAÇÃO | P11: 122 | Q11: ADMINISTRAÇÃO GERAL | R11: 0217 | S11: FOMENTO AO DESENVOLVIMENTO ECONÔMICO | T11: 2853 | U11: PROMOÇÃO E ATRAÇÃO DE INVESTIMENTOS E EMPREENDEDORISMO | V11: 339039 | W11: Despesa corrente | X11: Outras despesas correntes | Y11: 500 | Z11: SMDE | AA11: 70000 | AB11: 70000 | AC11: 70000 | AD11: 70000 | AF11: 0 | AG11: 0 | AH11: 0502 | AI11: =IF(AH11="","",IFERROR(RIGHT("0000"&AH11,4)&" - "&UPPER(_xlfn.XLOOKUP(RIGHT("0000"&AH11,4),CODEBOOK_CAP!$C$2:$C$212,CODEBOOK_CAP!$D$2:$D$212)),"Código CAP não encontrado")) -> 0502 - FORMAÇÃO E DESENVOLVIMENTO PROFISSIONAL | AJ11: =IF(AH11="","",IFERROR(_xlfn.XLOOKUP(RIGHT("0000"&AH11,4),CODEBOOK_CAP!$C$2:$C$212,CODEBOOK_CAP!$E$2:$E$212),"Código CAP não encontrado")) -> Programas de capacitação profissional, programas de incentivo ao emprego geral, reciclagem, realocação profissional em outra área, acordos e parcerias do estado com empresas privadas na capacitação, formação e treinamento profissional. | AK11: 0 | AM11: 0 | AN11: 0 | AP11: 1 | AQ11: quilombolas | AR11: 0 | AT11: Revisado | AU11: Alta | AV11: 46214
A12: 2023_BELLA_GONCALVES_896_01 | B12: 2023 | C12: 674 | D12: emendas-2023-27-11-2025.xlsx | E12: 2023_BELLA_GONCALVES | F12: 896 | G12: IMPEDIMENTO TÉCNICO | H12: Bella Gonçalves | J12: à pavimentação de via urbana na Regional Oeste, especificamente na Ocupação Novo Paraíso, bairro Palmeiras | K12: 2700.1545100621.230.449051.F.500 | L12: 2700 | M12: SECRETARIA MUNICIPAL DE OBRAS E INFRAESTRUTURA | N12: 15 | O12: URBANISMO | P12: 451 | Q12: INFRA-ESTRUTURA URBANA | R12: 0062 | S12: GESTÃO DO SISTEMA VIÁRIO MUNICIPAL | T12: 1230 | U12: IMPLANTAÇÃO E RECONSTRUÇÃO DE VIAS PÚBLICAS | V12: 449051 | W12: Despesa de capital | X12: Investimentos | Y12: 500 | Z12: SMOBI | AA12: 192532 | AB12: 0 | AC12: 0 | AD12: 0 | AF12: 0 | AG12: 0 | AH12: 1002 | AI12: =IF(AH12="","",IFERROR(RIGHT("0000"&AH12,4)&" - "&UPPER(_xlfn.XLOOKUP(RIGHT("0000"&AH12,4),CODEBOOK_CAP!$C$2:$C$212,CODEBOOK_CAP!$D$2:$D$212)),"Código CAP não encontrado")) -> 1002 - CARROS, TRÂNSITO, CONSTRUÇÃO E MANUTENÇÃO DE RUAS E ESTRADAS | AJ12: =IF(AH12="","",IFERROR(_xlfn.XLOOKUP(RIGHT("0000"&AH12,4),CODEBOOK_CAP!$C$2:$C$212,CODEBOOK_CAP!$E$2:$E$212),"Código CAP não encontrado")) -> Construção, manutenção de ruas, avenidas, estradas. BRs, pedágios, privatizações, concessinárias, segurança nas estradas, leis de trânsito relacionadas a via, limite de velocidade, sinalização, recapeamento de ruas, pavimentação estradas de terra, não pavimentadas, acidentes e camapanhas de prevencao contra acidentes de transito. Observações sobre regulação de transportes não públicos de carros, veículos de passeio, uber, taxi, transporte de cargas terrestre, frete, trânsito em vias públicas, regulamentação de tipos de carteira de motorista, especificações para caminhoneiros, testes e exames de habilitação, exigências de carteira de habilitação, obrigatoriedade de itens em veículos (extintor, kit primeiros socorros, airbag, freios abs) Quando tratar de grandes obras de construções de rodovias, olhar codigo 1010 para ver qual se encaixa melhor. | AK12: 1 | AL12: Regional Oeste, Ocupação Novo Paraíso, bairro Palmeiras | AM12: 1 | AN12: 0 | AP12: 0 | AR12: 0 | AT12: Revisado | AU12: Alta | AV12: 46214
A13: 2023_BIM_DA_AMBULANCIA_1063_01 | B13: 2023 | C13: 841 | D13: emendas-2023-27-11-2025.xlsx | E13: 2023_BIM_DA_AMBULANCIA | F13: 1063 | G13: CONCLUÍDO | H13: Bim da Ambulância | J13: Ao reforço de dotação orçamentária para o Centro de Saúde Paraúna, situado à rua João Ferreira da Silva, 248 - Bairro Mantiqueira - Venda Nova | K13: 2302.1030101572.690.339037.S.500 | L13: 2302 | M13: FUNDO MUNICIPAL DE SAÚDE | N13: 10 | O13: SAÚDE | P13: 301 | Q13: ATENÇÃO BÁSICA | R13: 0157 | S13: ATENÇÃO PRIMÁRIA À SAÚDE | T13: 2690 | U13: ATENÇÃO PRIMÁRIA À SAÚDE | V13: 339037 | W13: Despesa corrente | X13: Outras despesas correntes | Y13: 500 | Z13: FMS | AA13: 60000 | AB13: 60000 | AC13: 113052.63 | AD13: 60000 | AF13: 1 | AG13: 1 | AH13: 0322 | AI13: =IF(AH13="","",IFERROR(RIGHT("0000"&AH13,4)&" - "&UPPER(_xlfn.XLOOKUP(RIGHT("0000"&AH13,4),CODEBOOK_CAP!$C$2:$C$212,CODEBOOK_CAP!$D$2:$D$212)),"Código CAP não encontrado")) -> 0322 - ESTRUTURAS, HOSPITAIS, CLÍNICAS | AJ13: =IF(AH13="","",IFERROR(_xlfn.XLOOKUP(RIGHT("0000"&AH13,4),CODEBOOK_CAP!$C$2:$C$212,CODEBOOK_CAP!$E$2:$E$212),"Código CAP não encontrado")) -> Observações relacionadas as estruturas do sistema de saúde, como a construção de hospitais, postos de saúde, construção de maternidades, laboratórios, centros de saúde avançado, SAMU, Ambulâncias, UTI Móveis, leitos, compra de equipamentos médicos, Raio X, Ultrasom, equipamentos de diálise, capacidade de atendimento, estrutura e funcionamento de equipamentos públicos de saúde. | AK13: 1 | AL13: rua João Ferreira da Silva, 248 - Bairro Mantiqueira - Venda Nova | AM13: 1 | AN13: 1 | AO13: Centro de Saúde Paraúna (Rua João Ferreira da Silva, 248 - Bairro Mantiqueira - Venda Nova) | AP13: 0 | AR13: 0 | AT13: Revisado | AU13: Alta | AV13: 46214
A14: 2023_BIM_DA_AMBULANCIA_744_01 | B14: 2023 | C14: 530 | D14: emendas-2023-27-11-2025.xlsx | E14: 2023_BIM_DA_AMBULANCIA | F14: 744 | G14: IMPEDIMENTO TÉCNICO | H14: Bim da Ambulância | J14: Ao reforço de dotação orçamentária para construção de vestiários no Campo do itatiaia, situado à rua Clóvis Salgado, 1300 - Bandeirantes | K14: 2700.2781201011.213.449051.F.500 | L14: 2700 | M14: SECRETARIA MUNICIPAL DE OBRAS E INFRAESTRUTURA | N14: 27 | O14: DESPORTO E LAZER | P14: 812 | Q14: DESPORTO COMUNITÁRIO | R14: 0101 | S14: PROMOÇÃO E DEMOCRATIZAÇÃO DAS PRÁTICAS DE ESPORTES E LAZER | T14: 1213 | U14: CONSTRUÇÃO, AMPLIAÇÃO E REFORMA DE EQUIPAMENTOS ESPORTIVOS E ÁREAS DE LAZER | V14: 449051 | W14: Despesa de capital | X14: Investimentos | Y14: 500 | Z14: SMOBI | AA14: 210000 | AB14: 0 | AC14: 0 | AD14: 0 | AF14: 0 | AG14: 0 | AH14: 2300 | AI14: =IF(AH14="","",IFERROR(RIGHT("0000"&AH14,4)&" - "&UPPER(_xlfn.XLOOKUP(RIGHT("0000"&AH14,4),CODEBOOK_CAP!$C$2:$C$212,CODEBOOK_CAP!$D$2:$D$212)),"Código CAP não encontrado")) -> 2300 - GERAL | AJ14: =IF(AH14="","",IFERROR(_xlfn.XLOOKUP(RIGHT("0000"&AH14,4),CODEBOOK_CAP!$C$2:$C$212,CODEBOOK_CAP!$E$2:$E$212),"Código CAP não encontrado")) -> Observações relativas as políticas de cultura, Lei rouanet, patrimônio cultural, imaterial, políticas de artes, incentivos fiscais para artes, promoção de eventos culturais, amostras, teatro, dança, artes plásticas, artes visuais, museus, galerias públicas, idioma, lingua portuguesa. Grandes eventos esportivos, Copa do Mundo, Olimpiadas, Esporte e Lazer. | AK14: 1 | AL14: rua Clóvis Salgado, 1300 - Bandeirantes | AM14: 1 | AN14: 1 | AO14: Campo do itatiaia (rua Clóvis Salgado, 1300 - Bandeirantes) | AP14: 0 | AR14: 0 | AT14: Revisado | AU14: Alta | AV14: 46214 | AX14: esporte e lazer
A15: 2023_BIM_DA_AMBULANCIA_752_01 | B15: 2023 | C15: 538 | D15: emendas-2023-27-11-2025.xlsx | E15: 2023_BIM_DA_AMBULANCIA | F15: 752 | G15: CONCLUÍDO | H15: Bim da Ambulância | J15: Construção do Vestiário Feminino do Campo Telê Santana situado à rua Augusto dos Anjos, Bairro SINIMBU - CEP 31.535-000 | K15: 2700.0412202331.219.449051.F.500 | L15: 2700 | M15: SECRETARIA MUNICIPAL DE OBRAS E INFRAESTRUTURA | N15: 04 | O15: ADMINISTRAÇÃO | P15: 122 | Q15: ADMINISTRAÇÃO GERAL | R15: 0233 | S15: MANUTENÇÃO DA CIDADE | T15: 1219 | U15: AQUISIÇÃO, CONSTRUÇÃO, REFORMA E READAPTAÇÃO DE IMÓVEIS | V15: 449051 | W15: Despesa de capital | X15: Investimentos | Y15: 500 | Z15: SMOBI | AA15: 140000 | AB15: 8004.73 | AC15: 8004.73 | AD15: 8004.73 | AF15: 0 | AG15: 0 | AH15: 2300 | AI15: =IF(AH15="","",IFERROR(RIGHT("0000"&AH15,4)&" - "&UPPER(_xlfn.XLOOKUP(RIGHT("0000"&AH15,4),CODEBOOK_CAP!$C$2:$C$212,CODEBOOK_CAP!$D$2:$D$212)),"Código CAP não encontrado")) -> 2300 - GERAL | AJ15: =IF(AH15="","",IFERROR(_xlfn.XLOOKUP(RIGHT("0000"&AH15,4),CODEBOOK_CAP!$C$2:$C$212,CODEBOOK_CAP!$E$2:$E$212),"Código CAP não encontrado")) -> Observações relativas as políticas de cultura, Lei rouanet, patrimônio cultural, imaterial, políticas de artes, incentivos fiscais para artes, promoção de eventos culturais, amostras, teatro, dança, artes plásticas, artes visuais, museus, galerias públicas, idioma, lingua portuguesa. Grandes eventos esportivos, Copa do Mundo, Olimpiadas, Esporte e Lazer. | AK15: 1 | AL15: rua Augusto dos Anjos, Bairro SINIMBU - CEP 31.535-000 | AM15: 1 | AN15: 1 | AO15: Campo Telê Santana (Rua Augusto dos Anjos, Bairro SINIMBU - CEP 31.535-000) | AP15: 1 | AQ15: mulheres | AR15: 0 | AT15: Revisado | AU15: Alta | AV15: 46214 | AX15: esporte e lazer
A16: 2023_BIM_DA_AMBULANCIA_753_01 | B16: 2023 | C16: 539 | D16: emendas-2023-27-11-2025.xlsx | E16: 2023_BIM_DA_AMBULANCIA | F16: 753 | G16: CONCLUÍDO | H16: Bim da Ambulância | J16: Reforma do Sine Venda Nova, situado à rua Padre Pedro Pinto, 1055 - Bairro Venda Nova | K16: 2700.0412202331.219.449051.F.500 | L16: 2700 | M16: SECRETARIA MUNICIPAL DE OBRAS E INFRAESTRUTURA | N16: 04 | O16: ADMINISTRAÇÃO | P16: 122 | Q16: ADMINISTRAÇÃO GERAL | R16: 0233 | S16: MANUTENÇÃO DA CIDADE | T16: 1219 | U16: AQUISIÇÃO, CONSTRUÇÃO, REFORMA E READAPTAÇÃO DE IMÓVEIS | V16: 449051 | W16: Despesa de capital | X16: Investimentos | Y16: 500 | Z16: SMOBI | AA16: 150000 | AB16: 40973.65 | AC16: 40973.65 | AD16: 40973.65 | AF16: 0 | AG16: 0 | AH16: 0599 | AI16: =IF(AH16="","",IFERROR(RIGHT("0000"&AH16,4)&" - "&UPPER(_xlfn.XLOOKUP(RIGHT("0000"&AH16,4),CODEBOOK_CAP!$C$2:$C$212,CODEBOOK_CAP!$D$2:$D$212)),"Código CAP não encontrado")) -> 0599 - OUTROS | AJ16: =IF(AH16="","",IFERROR(_xlfn.XLOOKUP(RIGHT("0000"&AH16,4),CODEBOOK_CAP!$C$2:$C$212,CODEBOOK_CAP!$E$2:$E$212),"Código CAP não encontrado")) -> Observações que versam sobre TRABALHO E EMPREGO, mas que não se enquadram em nenhum dos itens acima. | AK16: 1 | AL16: rua Padre Pedro Pinto, 1055 - Bairro Venda Nova | AM16: 1 | AN16: 1 | AO16: rua Padre Pedro Pinto, 1055 - Bairro Venda Nova | AP16: 0 | AR16: 0 | AT16: Revisado | AU16: Alta | AV16: 46214
A17: 2023_BIM_DA_AMBULANCIA_754_01 | B17: 2023 | C17: 540 | D17: emendas-2023-27-11-2025.xlsx | E17: 2023_BIM_DA_AMBULANCIA | F17: 754 | G17: CONCLUÍDO | H17: Bim da Ambulância | J17: Reforma do telhado da CARE Venda Nova, situado à Rua Padre Pedro Pinto, 1055 - Bairro Venda Nova | K17: 2700.0412202331.219.449051.F.500 | L17: 2700 | M17: SECRETARIA MUNICIPAL DE OBRAS E INFRAESTRUTURA | N17: 04 | O17: ADMINISTRAÇÃO | P17: 122 | Q17: ADMINISTRAÇÃO GERAL | R17: 0233 | S17: MANUTENÇÃO DA CIDADE | T17: 1219 | U17: AQUISIÇÃO, CONSTRUÇÃO, REFORMA E READAPTAÇÃO DE IMÓVEIS | V17: 449051 | W17: Despesa de capital | X17: Investimentos | Y17: 500 | Z17: SMOBI | AA17: 150000 | AB17: 0 | AC17: 0 | AD17: 0 | AF17: 0 | AG17: 0 | AH17: 2002 | AI17: =IF(AH17="","",IFERROR(RIGHT("0000"&AH17,4)&" - "&UPPER(_xlfn.XLOOKUP(RIGHT("0000"&AH17,4),CODEBOOK_CAP!$C$2:$C$212,CODEBOOK_CAP!$D$2:$D$212)),"Código CAP não encontrado")) -> 2002 - BUROCRACIA, EFICIÊNCIA E FUNCIONAMENTO DA ADMINISTRAÇÃO PÚBLICA | AJ17: =IF(AH17="","",IFERROR(_xlfn.XLOOKUP(RIGHT("0000"&AH17,4),CODEBOOK_CAP!$C$2:$C$212,CODEBOOK_CAP!$E$2:$E$212),"Código CAP não encontrado")) -> Assuntos relacionados aos modelos de administração pública, serviços público, burocracia, e eficiência dos serviços e do aparato público. Funcionamento e organização da administração Pública. Repartições, serviços. Atuação direta para o cidadão, POUPATEMPO, desburocratização da administração pública, informatização do setor público, oferta de serviços públicos online. | AK17: 1 | AL17: Rua Padre Pedro Pinto, 1055 - Bairro Venda Nova | AM17: 1 | AN17: 1 | AO17: Rua Padre Pedro Pinto, 1055 - Bairro Venda Nova | AP17: 0 | AR17: 0 | AT17: Revisado | AU17: Alta | AV17: 46214
A18: 2023_BIM_DA_AMBULANCIA_757_01 | B18: 2023 | C18: 541 | D18: emendas-2023-27-11-2025.xlsx | E18: 2023_BIM_DA_AMBULANCIA | F18: 757 | G18: IMPEDIMENTO TÉCNICO | H18: Bim da Ambulância | J18: À realização de ações de assistência social pela entidade: Associação Mineira de Educação Continuada - ASMEC CNPJ 05.263.848/0001-27 na qualificação profissional e inclusão produtiva. | K18: 1011.0824400192.308.339039.S.500 | L18: 1011 | M18: FUNDO MUNICIPAL DE ASSISTÊNCIA SOCIAL | N18: 08 | O18: ASSISTÊNCIA SOCIAL | P18: 244 | Q18: ASSISTÊNCIA COMUNITÁRIA | R18: 0019 | S18: PROTEÇÃO SOCIAL BÁSICA | T18: 2308 | U18: SERVIÇOS DE PROTEÇÃO SOCIAL BÁSICA | V18: 339039 | W18: Despesa corrente | X18: Outras despesas correntes | Y18: 500 | Z18: SMASDH | AA18: 806266 | AB18: 0 | AC18: 0 | AD18: 0 | AF18: 0 | AG18: 0 | AH18: 0502 | AI18: =IF(AH18="","",IFERROR(RIGHT("0000"&AH18,4)&" - "&UPPER(_xlfn.XLOOKUP(RIGHT("0000"&AH18,4),CODEBOOK_CAP!$C$2:$C$212,CODEBOOK_CAP!$D$2:$D$212)),"Código CAP não encontrado")) -> 0502 - FORMAÇÃO E DESENVOLVIMENTO PROFISSIONAL | AJ18: =IF(AH18="","",IFERROR(_xlfn.XLOOKUP(RIGHT("0000"&AH18,4),CODEBOOK_CAP!$C$2:$C$212,CODEBOOK_CAP!$E$2:$E$212),"Código CAP não encontrado")) -> Programas de capacitação profissional, programas de incentivo ao emprego geral, reciclagem, realocação profissional em outra área, acordos e parcerias do estado com empresas privadas na capacitação, formação e treinamento profissional. | AK18: 0 | AM18: 0 | AN18: 0 | AP18: 0 | AR18: 0 | AT18: Revisado | AU18: Alta | AV18: 46214
A19: 2023_BIM_DA_AMBULANCIA_758_01 | B19: 2023 | C19: 542 | D19: emendas-2023-27-11-2025.xlsx | E19: 2023_BIM_DA_AMBULANCIA | F19: 758 | G19: CONCLUÍDO | H19: Bim da Ambulância | J19: Manutenção de Rede de Drenagem da rua Edgard Torres - Minas Caixa - Venda Nova. | K19: 2700.1545102331.396.449051.F.500 | L19: 2700 | M19: SECRETARIA MUNICIPAL DE OBRAS E INFRAESTRUTURA | N19: 15 | O19: URBANISMO | P19: 451 | Q19: INFRA-ESTRUTURA URBANA | R19: 0233 | S19: MANUTENÇÃO DA CIDADE | T19: 1396 | U19: INFRAESTRUTURA URBANA | V19: 449051 | W19: Despesa de capital | X19: Investimentos | Y19: 500 | Z19: SMOBI | AA19: 30000 | AB19: 21000.67 | AC19: 21000.67 | AD19: 21000.67 | AF19: 0 | AG19: 0 | AH19: 0711 | AI19: =IF(AH19="","",IFERROR(RIGHT("0000"&AH19,4)&" - "&UPPER(_xlfn.XLOOKUP(RIGHT("0000"&AH19,4),CODEBOOK_CAP!$C$2:$C$212,CODEBOOK_CAP!$D$2:$D$212)),"Código CAP não encontrado")) -> 0711 - CONSERVAÇÃO DO SOLO, MAR, RIOS, PRAIAS E COSTAS | AJ19: =IF(AH19="","",IFERROR(_xlfn.XLOOKUP(RIGHT("0000"&AH19,4),CODEBOOK_CAP!$C$2:$C$212,CODEBOOK_CAP!$E$2:$E$212),"Código CAP não encontrado")) -> Poluição de oceanos, regulamentação de acesso e conservação da costa, ilhas, praias, mangues, e assuntos relacionados ao mar, oceanos e litoral. Erosão de terrenos, morros, promoção da qualidade do solo, conservação de rios, lagos e afluentes, questões vinculadas a enchentes, poluição urbana, margens, encostas de rios, chuvas, temporais, tempestades, terrenos contaminados, rios contamidados e poluidos, fertilizantes. Quando assunto for uso dos recursos naturais usar codigo 21. 2104 para recursos hídricos, 2103 para recursos naturais como minerais. Quando o assunto for tratamento de água potável, distribuição de água potável para residencias, 701. | AK19: 1 | AL19: rua Edgard Torres - Minas Caixa - Venda Nova. | AM19: 1 | AN19: 1 | AO19: rua Edgard Torres - Minas Caixa - Venda Nova. | AP19: 0 | AR19: 0 | AT19: Revisado | AU19: Alta | AV19: 46214
A20: 2023_BIM_DA_AMBULANCIA_759_01 | B20: 2023 | C20: 543 | D20: emendas-2023-27-11-2025.xlsx | E20: 2023_BIM_DA_AMBULANCIA | F20: 759 | G20: CONCLUÍDO | H20: Bim da Ambulância | J20: Revitalização da Praça São Caetano do Sul, situada entre as ruas Cyrene Bellonia e Hélio Pellegrino - São João Batista - Venda Nova | K20: 2700.1545102331.202.449051.F.500 | L20: 2700 | M20: SECRETARIA MUNICIPAL DE OBRAS E INFRAESTRUTURA | N20: 15 | O20: URBANISMO | P20: 451 | Q20: INFRA-ESTRUTURA URBANA | R20: 0233 | S20: MANUTENÇÃO DA CIDADE | T20: 1202 | U20: CONSTRUÇÃO, AMPLIAÇÃO E REFORMA DE PRAÇAS, PARQUES E CANTEIROS | V20: 449051 | W20: Despesa de capital | X20: Investimentos | Y20: 500 | Z20: SMOBI | AA20: 126266 | AB20: 112626.8 | AC20: 112626.8 | AD20: 112626.8 | AF20: 0 | AG20: 0 | AH20: 1403 | AI20: =IF(AH20="","",IFERROR(RIGHT("0000"&AH20,4)&" - "&UPPER(_xlfn.XLOOKUP(RIGHT("0000"&AH20,4),CODEBOOK_CAP!$C$2:$C$212,CODEBOOK_CAP!$D$2:$D$212)),"Código CAP não encontrado")) -> 1403 - REABILITAÇÃO URBANA, ECONOMIA URBANA | AJ20: =IF(AH20="","",IFERROR(_xlfn.XLOOKUP(RIGHT("0000"&AH20,4),CODEBOOK_CAP!$C$2:$C$212,CODEBOOK_CAP!$E$2:$E$212),"Código CAP não encontrado")) -> Reabilitação de áreas urbanas, revitalização urbana, modernização de áreas, mercados públicos, revitalização de praças, política urbana nacional, desenvolvimento urbano , desenvolvimento econômico de estados e cidades, modernização de espaços urbanos | AK20: 1 | AL20: Praça São Caetano do Sul, situada entre as ruas Cyrene Bellonia e Hélio Pellegrino - São João Batista - Venda Nova | AM20: 1 | AN20: 1 | AO20: Praça São Caetano do Sul, situada entre as ruas Cyrene Bellonia e Hélio Pellegrino - São João Batista - Venda Nova | AP20: 0 | AR20: 0 | AT20: Revisado | AU20: Alta | AV20: 46214
A21: 2023_BIM_DA_AMBULANCIA_803_01 | B21: 2023 | C21: 582 | D21: emendas-2023-27-11-2025.xlsx | E21: 2023_BIM_DA_AMBULANCIA | F21: 803 | G21: CONCLUÍDO | H21: Bim da Ambulância | J21: À aquisição de materiais permanentes para o Centro de Saúde Santo Antônio na Regional Venda Nova, situado à rua Irineu Pinto, 255 - São João Batista. | K21: 2302.1030101572.690.449052.S.500 | L21: 2302 | M21: FUNDO MUNICIPAL DE SAÚDE | N21: 10 | O21: SAÚDE | P21: 301 | Q21: ATENÇÃO BÁSICA | R21: 0157 | S21: ATENÇÃO PRIMÁRIA À SAÚDE | T21: 2690 | U21: ATENÇÃO PRIMÁRIA À SAÚDE | V21: 449052 | W21: Despesa de capital | X21: Investimentos | Y21: 500 | Z21: FMS | AA21: 7000 | AB21: 6706 | AC21: 6706 | AD21: 6706 | AF21: 1 | AG21: 1 | AH21: 0322 | AI21: =IF(AH21="","",IFERROR(RIGHT("0000"&AH21,4)&" - "&UPPER(_xlfn.XLOOKUP(RIGHT("0000"&AH21,4),CODEBOOK_CAP!$C$2:$C$212,CODEBOOK_CAP!$D$2:$D$212)),"Código CAP não encontrado")) -> 0322 - ESTRUTURAS, HOSPITAIS, CLÍNICAS | AJ21: =IF(AH21="","",IFERROR(_xlfn.XLOOKUP(RIGHT("0000"&AH21,4),CODEBOOK_CAP!$C$2:$C$212,CODEBOOK_CAP!$E$2:$E$212),"Código CAP não encontrado")) -> Observações relacionadas as estruturas do sistema de saúde, como a construção de hospitais, postos de saúde, construção de maternidades, laboratórios, centros de saúde avançado, SAMU, Ambulâncias, UTI Móveis, leitos, compra de equipamentos médicos, Raio X, Ultrasom, equipamentos de diálise, capacidade de atendimento, estrutura e funcionamento de equipamentos públicos de saúde. | AK21: 1 | AL21: Centro de Saúde Santo Antônio na Regional Venda Nova, situado à rua Irineu Pinto, 255 - São João Batista. | AM21: 1 | AN21: 1 | AO21: Centro de Saúde Santo Antônio na Regional Venda Nova, situado à rua Irineu Pinto, 255 - São João Batista. | AP21: 0 | AR21: 0 | AT21: Revisado | AU21: Alta | AV21: 46214
A22: 2023_BIM_DA_AMBULANCIA_810_01 | B22: 2023 | C22: 589 | D22: emendas-2023-27-11-2025.xlsx | E22: 2023_BIM_DA_AMBULANCIA | F22: 810 | G22: EM EXECUÇÃO | H22: Bim da Ambulância | J22: À aquisição de material permanente para o Centro de Saúde Minas Caixa na Regional Venda Nova, situado à rua Capitão Sérgio Pires, 226 - Bairro Minas Caixa. | K22: 2302.1030101572.690.449052.S.500 | L22: 2302 | M22: FUNDO MUNICIPAL DE SAÚDE | N22: 10 | O22: SAÚDE | P22: 301 | Q22: ATENÇÃO BÁSICA | R22: 0157 | S22: ATENÇÃO PRIMÁRIA À SAÚDE | T22: 2690 | U22: ATENÇÃO PRIMÁRIA À SAÚDE | V22: 449052 | W22: Despesa de capital | X22: Investimentos | Y22: 500 | Z22: FMS | AA22: 4000 | AB22: 2790.51 | AC22: 2013.11 | AD22: 2013.11 | AE22: INSMART COMERCIO DE EQUIPAMENTOS LTDA | AF22: 1 | AG22: 1 | AH22: 0322 | AI22: =IF(AH22="","",IFERROR(RIGHT("0000"&AH22,4)&" - "&UPPER(_xlfn.XLOOKUP(RIGHT("0000"&AH22,4),CODEBOOK_CAP!$C$2:$C$212,CODEBOOK_CAP!$D$2:$D$212)),"Código CAP não encontrado")) -> 0322 - ESTRUTURAS, HOSPITAIS, CLÍNICAS | AJ22: =IF(AH22="","",IFERROR(_xlfn.XLOOKUP(RIGHT("0000"&AH22,4),CODEBOOK_CAP!$C$2:$C$212,CODEBOOK_CAP!$E$2:$E$212),"Código CAP não encontrado")) -> Observações relacionadas as estruturas do sistema de saúde, como a construção de hospitais, postos de saúde, construção de maternidades, laboratórios, centros de saúde avançado, SAMU, Ambulâncias, UTI Móveis, leitos, compra de equipamentos médicos, Raio X, Ultrasom, equipamentos de diálise, capacidade de atendimento, estrutura e funcionamento de equipamentos públicos de saúde. | AK22: 1 | AL22: Centro de Saúde Minas Caixa na Regional Venda Nova, situado à rua Capitão Sérgio Pires, 226 - Bairro Minas Caixa. | AM22: 1 | AN22: 1 | AO22: Centro de Saúde Minas Caixa na Regional Venda Nova, situado à rua Capitão Sérgio Pires, 226 - Bairro Minas Caixa. | AP22: 0 | AR22: 1 | AS22: INSMART COMERCIO DE EQUIPAMENTOS LTDA | AT22: Revisado | AU22: Alta | AV22: 46214
A23: 2023_BIM_DA_AMBULANCIA_811_01 | B23: 2023 | C23: 590 | D23: emendas-2023-27-11-2025.xlsx | E23: 2023_BIM_DA_AMBULANCIA | F23: 811 | G23: EM EXECUÇÃO | H23: Bim da Ambulância | J23: À aquisição de materiais permanentes para o Centro de Saúde Andradas, na Regional Venda Nova, situado à rua Mariana Amélia de Azevedo, 21 - Bairro São João Batista | K23: 2302.1030101572.690.449052.S.500 | L23: 2302 | M23: FUNDO MUNICIPAL DE SAÚDE | N23: 10 | O23: SAÚDE | P23: 301 | Q23: ATENÇÃO BÁSICA | R23: 0157 | S23: ATENÇÃO PRIMÁRIA À SAÚDE | T23: 2690 | U23: ATENÇÃO PRIMÁRIA À SAÚDE | V23: 449052 | W23: Despesa de capital | X23: Investimentos | Y23: 500 | Z23: FMS | AA23: 45000 | AB23: 9518.4599999999991 | AC23: 8648.4599999999991 | AD23: 8648.4599999999991 | AE23: B. D. R. COMERCIO DE EQUIPAMENTOS LTDA | AF23: 1 | AG23: 1 | AH23: 0322 | AI23: =IF(AH23="","",IFERROR(RIGHT("0000"&AH23,4)&" - "&UPPER(_xlfn.XLOOKUP(RIGHT("0000"&AH23,4),CODEBOOK_CAP!$C$2:$C$212,CODEBOOK_CAP!$D$2:$D$212)),"Código CAP não encontrado")) -> 0322 - ESTRUTURAS, HOSPITAIS, CLÍNICAS | AJ23: =IF(AH23="","",IFERROR(_xlfn.XLOOKUP(RIGHT("0000"&AH23,4),CODEBOOK_CAP!$C$2:$C$212,CODEBOOK_CAP!$E$2:$E$212),"Código CAP não encontrado")) -> Observações relacionadas as estruturas do sistema de saúde, como a construção de hospitais, postos de saúde, construção de maternidades, laboratórios, centros de saúde avançado, SAMU, Ambulâncias, UTI Móveis, leitos, compra de equipamentos médicos, Raio X, Ultrasom, equipamentos de diálise, capacidade de atendimento, estrutura e funcionamento de equipamentos públicos de saúde. | AK23: 1 | AL23: Centro de Saúde Andradas, na Regional Venda Nova, situado à rua Mariana Amélia de Azevedo, 21 - Bairro São João Batista | AM23: 1 | AN23: 1 | AO23: Centro de Saúde Andradas, na Regional Venda Nova, situado à rua Mariana Amélia de Azevedo, 21 - Bairro São João Batista | AP23: 0 | AR23: 1 | AS23: B. D. R. COMERCIO DE EQUIPAMENTOS LTDA | AT23: Revisado | AU23: Alta | AV23: 46214
A24: 2023_BIM_DA_AMBULANCIA_812_01 | B24: 2023 | C24: 591 | D24: emendas-2023-27-11-2025.xlsx | E24: 2023_BIM_DA_AMBULANCIA | F24: 812 | G24: EM EXECUÇÃO | H24: Bim da Ambulância | J24: À aquisição de materiais permanentes para o Centro de Saúde Lagoa, na Regional Venda Nova, situado na rua José Sabino Maciel, 176 - Bairro Lagoa, CEP: 31578-060. | K24: 2302.1030101572.690.449052.S.500 | L24: 2302 | M24: FUNDO MUNICIPAL DE SAÚDE | N24: 10 | O24: SAÚDE | P24: 301 | Q24: ATENÇÃO BÁSICA | R24: 0157 | S24: ATENÇÃO PRIMÁRIA À SAÚDE | T24: 2690 | U24: ATENÇÃO PRIMÁRIA À SAÚDE | V24: 449052 | W24: Despesa de capital | X24: Investimentos | Y24: 500 | Z24: FMS | AA24: 35000 | AB24: 27776.400000000001 | AC24: 26036.400000000001 | AD24: 26036.400000000001 | AE24: B. D. R. COMERCIO DE EQUIPAMENTOS LTDA; SUPORTH CIRURGICA PONTA GROSSA LTDA | AF24: 1 | AG24: 1 | AH24: 0322 | AI24: =IF(AH24="","",IFERROR(RIGHT("0000"&AH24,4)&" - "&UPPER(_xlfn.XLOOKUP(RIGHT("0000"&AH24,4),CODEBOOK_CAP!$C$2:$C$212,CODEBOOK_CAP!$D$2:$D$212)),"Código CAP não encontrado")) -> 0322 - ESTRUTURAS, HOSPITAIS, CLÍNICAS | AJ24: =IF(AH24="","",IFERROR(_xlfn.XLOOKUP(RIGHT("0000"&AH24,4),CODEBOOK_CAP!$C$2:$C$212,CODEBOOK_CAP!$E$2:$E$212),"Código CAP não encontrado")) -> Observações relacionadas as estruturas do sistema de saúde, como a construção de hospitais, postos de saúde, construção de maternidades, laboratórios, centros de saúde avançado, SAMU, Ambulâncias, UTI Móveis, leitos, compra de equipamentos médicos, Raio X, Ultrasom, equipamentos de diálise, capacidade de atendimento, estrutura e funcionamento de equipamentos públicos de saúde. | AK24: 1 | AL24: Centro de Saúde Lagoa, na Regional Venda Nova, situado na rua José Sabino Maciel, 176 - Bairro Lagoa, CEP: 31578-060. | AM24: 1 | AN24: 1 | AO24: Centro de Saúde Lagoa, na Regional Venda Nova, situado na rua José Sabino Maciel, 176 - Bairro Lagoa, CEP: 31578-060. | AP24: 0 | AR24: 1 | AS24: B. D. R. COMERCIO DE EQUIPAMENTOS LTDA; SUPORTH CIRURGICA PONTA GROSSA LTDA | AT24: Revisado | AU24: Alta | AV24: 46214
A25: 2023_BIM_DA_AMBULANCIA_813_01 | B25: 2023 | C25: 592 | D25: emendas-2023-27-11-2025.xlsx | E25: 2023_BIM_DA_AMBULANCIA | F25: 813 | G25: EM EXECUÇÃO | H25: Bim da Ambulância | J25: À aquisição de materiais permanentes para o Centro de Assistência à Mulher na UPA Venda Nova, situado à rua Padre Pedro Pinto, 322 - Venda Nova - CEP: 31610-000 | K25: 2302.1030201142.893.449052.S.500 | L25: 2302 | M25: FUNDO MUNICIPAL DE SAÚDE | N25: 10 | O25: SAÚDE | P25: 302 | Q25: ASSISTÊNCIA HOSPITALAR E AMBULATORIAL | R25: 0114 | S25: ATENÇÃO SECUNDÁRIA E TERCIÁRIA À SAÚDE | T25: 2893 | U25: REDE DE URGÊNCIA E EMERGÊNCIA | V25: 449052 | W25: Despesa de capital | X25: Investimentos | Y25: 500 | Z25: FMS | AA25: 250000 | AB25: 195230 | AC25: 820 | AD25: 820 | AE25: ADEM DISTRIBUIDORA DE EQUIPAMENTOS MEDICOS LTDA; MARCENARIA SANTA CLARA LTDA; RJN COMERCIO DE MAQUINAS, APARELHOS E EQUIPAMENTOS LTDA; SENA E PRATES LTDA | AF25: 1 | AG25: 1 | AH25: 0322 | AI25: =IF(AH25="","",IFERROR(RIGHT("0000"&AH25,4)&" - "&UPPER(_xlfn.XLOOKUP(RIGHT("0000"&AH25,4),CODEBOOK_CAP!$C$2:$C$212,CODEBOOK_CAP!$D$2:$D$212)),"Código CAP não encontrado")) -> 0322 - ESTRUTURAS, HOSPITAIS, CLÍNICAS | AJ25: =IF(AH25="","",IFERROR(_xlfn.XLOOKUP(RIGHT("0000"&AH25,4),CODEBOOK_CAP!$C$2:$C$212,CODEBOOK_CAP!$E$2:$E$212),"Código CAP não encontrado")) -> Observações relacionadas as estruturas do sistema de saúde, como a construção de hospitais, postos de saúde, construção de maternidades, laboratórios, centros de saúde avançado, SAMU, Ambulâncias, UTI Móveis, leitos, compra de equipamentos médicos, Raio X, Ultrasom, equipamentos de diálise, capacidade de atendimento, estrutura e funcionamento de equipamentos públicos de saúde. | AK25: 1 | AL25: Centro de Assistência à Mulher na UPA Venda Nova, situado à rua Padre Pedro Pinto, 322 - Venda Nova - CEP: 31610-000 | AM25: 1 | AN25: 1 | AO25: Centro de Assistência à Mulher na UPA Venda Nova, situado à rua Padre Pedro Pinto, 322 - Venda Nova - CEP: 31610-000 | AP25: 1 | AQ25: mulheres | AR25: 1 | AS25: ADEM DISTRIBUIDORA DE EQUIPAMENTOS MEDICOS LTDA; MARCENARIA SANTA CLARA LTDA; RJN COMERCIO DE MAQUINAS, APARELHOS E EQUIPAMENTOS LTDA; SENA E PRATES LTDA | AT25: Revisado | AU25: Alta | AV25: 46214
A26: 2023_BIM_DA_AMBULANCIA_814_01 | B26: 2023 | C26: 593 | D26: emendas-2023-27-11-2025.xlsx | E26: 2023_BIM_DA_AMBULANCIA | F26: 814 | G26: CONCLUÍDO | H26: Bim da Ambulância | J26: Melhorias e Reformas para o Centro de Saúde Santo Antônio, localizado à rua Irineu pinto, 255 - Bairro São João Batista - Regional Venda Nova | K26: 2302.1012201171.216.449051.S.500 | L26: 2302 | M26: FUNDO MUNICIPAL DE SAÚDE | N26: 10 | O26: SAÚDE | P26: 122 | Q26: ADMINISTRAÇÃO GERAL | R26: 0117 | S26: GESTÃO DO SUS | T26: 1216 | U26: CONSTRUÇÃO, AMPLIAÇÃO E REFORMA DE UNIDADES DE SAÚDE | V26: 449051 | W26: Despesa de capital | X26: Investimentos | Y26: 500 | Z26: FMS/SMOBI | AA26: 120000 | AB26: 97682.11 | AC26: 97682.11 | AD26: 97682.11 | AF26: 1 | AG26: 1 | AH26: 0322 | AI26: =IF(AH26="","",IFERROR(RIGHT("0000"&AH26,4)&" - "&UPPER(_xlfn.XLOOKUP(RIGHT("0000"&AH26,4),CODEBOOK_CAP!$C$2:$C$212,CODEBOOK_CAP!$D$2:$D$212)),"Código CAP não encontrado")) -> 0322 - ESTRUTURAS, HOSPITAIS, CLÍNICAS | AJ26: =IF(AH26="","",IFERROR(_xlfn.XLOOKUP(RIGHT("0000"&AH26,4),CODEBOOK_CAP!$C$2:$C$212,CODEBOOK_CAP!$E$2:$E$212),"Código CAP não encontrado")) -> Observações relacionadas as estruturas do sistema de saúde, como a construção de hospitais, postos de saúde, construção de maternidades, laboratórios, centros de saúde avançado, SAMU, Ambulâncias, UTI Móveis, leitos, compra de equipamentos médicos, Raio X, Ultrasom, equipamentos de diálise, capacidade de atendimento, estrutura e funcionamento de equipamentos públicos de saúde. | AK26: 1 | AL26: Centro de Saúde Santo Antônio, localizado à rua Irineu pinto, 255 - Bairro São João Batista - Regional Venda Nova | AM26: 1 | AN26: 1 | AO26: Centro de Saúde Santo Antônio, localizado à rua Irineu pinto, 255 - Bairro São João Batista - Regional Venda Nova | AP26: 0 | AR26: 0 | AT26: Revisado | AU26: Alta | AV26: 46214
A27: 2023_BIM_DA_AMBULANCIA_815_01 | B27: 2023 | C27: 594 | D27: emendas-2023-27-11-2025.xlsx | E27: 2023_BIM_DA_AMBULANCIA | F27: 815 | G27: CONCLUÍDO | H27: Bim da Ambulância | J27: Reforço de dotação orçamentária para instalação de telhada no Centro de Saúde Jardim Europa, situado à Rua Edimburgo, 140 - Jardim Europa - Regional Venda Nova | K27: 2302.1012201171.216.449051.S.500 | L27: 2302 | M27: FUNDO MUNICIPAL DE SAÚDE | N27: 10 | O27: SAÚDE | P27: 122 | Q27: ADMINISTRAÇÃO GERAL | R27: 0117 | S27: GESTÃO DO SUS | T27: 1216 | U27: CONSTRUÇÃO, AMPLIAÇÃO E REFORMA DE UNIDADES DE SAÚDE | V27: 449051 | W27: Despesa de capital | X27: Investimentos | Y27: 500 | Z27: FMS/SMOBI | AA27: 12000 | AB27: 0 | AC27: 0 | AD27: 0 | AF27: 1 | AG27: 1 | AH27: 0322 | AI27: =IF(AH27="","",IFERROR(RIGHT("0000"&AH27,4)&" - "&UPPER(_xlfn.XLOOKUP(RIGHT("0000"&AH27,4),CODEBOOK_CAP!$C$2:$C$212,CODEBOOK_CAP!$D$2:$D$212)),"Código CAP não encontrado")) -> 0322 - ESTRUTURAS, HOSPITAIS, CLÍNICAS | AJ27: =IF(AH27="","",IFERROR(_xlfn.XLOOKUP(RIGHT("0000"&AH27,4),CODEBOOK_CAP!$C$2:$C$212,CODEBOOK_CAP!$E$2:$E$212),"Código CAP não encontrado")) -> Observações relacionadas as estruturas do sistema de saúde, como a construção de hospitais, postos de saúde, construção de maternidades, laboratórios, centros de saúde avançado, SAMU, Ambulâncias, UTI Móveis, leitos, compra de equipamentos médicos, Raio X, Ultrasom, equipamentos de diálise, capacidade de atendimento, estrutura e funcionamento de equipamentos públicos de saúde. | AK27: 1 | AL27: Rua Edimburgo, 140 - Jardim Europa - Regional Venda Nova | AM27: 1 | AN27: 1 | AO27: Centro de Saúde Jardim Europa (Rua Edimburgo, 140 - Jardim Europa - Regional Venda Nova) | AP27: 0 | AR27: 0 | AT27: Revisado | AU27: Alta | AV27: 46214
A28: 2023_BIM_DA_AMBULANCIA_816_01 | B28: 2023 | C28: 595 | D28: emendas-2023-27-11-2025.xlsx | E28: 2023_BIM_DA_AMBULANCIA | F28: 816 | G28: EM EXECUÇÃO | H28: Bim da Ambulância | J28: À aquisição de materiais permanentes para o centro de Saúde Jardim Europa na Regional Venda Nova, situado à rua Edimburgo, 149 - Bairro Jardim Europa. | K28: 2302.1030101572.690.449052.S.500 | L28: 2302 | M28: FUNDO MUNICIPAL DE SAÚDE | N28: 10 | O28: SAÚDE | P28: 301 | Q28: ATENÇÃO BÁSICA | R28: 0157 | S28: ATENÇÃO PRIMÁRIA À SAÚDE | T28: 2690 | U28: ATENÇÃO PRIMÁRIA À SAÚDE | V28: 449052 | W28: Despesa de capital | X28: Investimentos | Y28: 500 | Z28: FMS | AA28: 40000 | AB28: 27606.22 | AC28: 1521.22 | AD28: 1521.22 | AE28: UDILIFE COM IMPORTACAO E EXPORTACAO LTDA | AF28: 1 | AG28: 1 | AH28: 0322 | AI28: =IF(AH28="","",IFERROR(RIGHT("0000"&AH28,4)&" - "&UPPER(_xlfn.XLOOKUP(RIGHT("0000"&AH28,4),CODEBOOK_CAP!$C$2:$C$212,CODEBOOK_CAP!$D$2:$D$212)),"Código CAP não encontrado")) -> 0322 - ESTRUTURAS, HOSPITAIS, CLÍNICAS | AJ28: =IF(AH28="","",IFERROR(_xlfn.XLOOKUP(RIGHT("0000"&AH28,4),CODEBOOK_CAP!$C$2:$C$212,CODEBOOK_CAP!$E$2:$E$212),"Código CAP não encontrado")) -> Observações relacionadas as estruturas do sistema de saúde, como a construção de hospitais, postos de saúde, construção de maternidades, laboratórios, centros de saúde avançado, SAMU, Ambulâncias, UTI Móveis, leitos, compra de equipamentos médicos, Raio X, Ultrasom, equipamentos de diálise, capacidade de atendimento, estrutura e funcionamento de equipamentos públicos de saúde. | AK28: 1 | AL28: Regional Venda Nova, situado à rua Edimburgo, 149 - Bairro Jardim Europa. | AM28: 1 | AN28: 1 | AO28: centro de Saúde Jardim Europa (Regional Venda Nova, situado à rua Edimburgo, 149 - Bairro Jardim Europa.) | AP28: 0 | AR28: 1 | AS28: UDILIFE COM IMPORTACAO E EXPORTACAO LTDA | AT28: Revisado | AU28: Alta | AV28: 46214
A29: 2023_BIM_DA_AMBULANCIA_817_01 | B29: 2023 | C29: 596 | D29: emendas-2023-27-11-2025.xlsx | E29: 2023_BIM_DA_AMBULANCIA | F29: 817 | G29: IMPEDIMENTO TÉCNICO | H29: Bim da Ambulância | J29: Ampliação da Farmácia, Construção de Banheiro e Colocação de Calha para o Telhado do Centro de Saúde Minas Caixa, localizado à Rua capitão Sérgio Pires, 226 - Bairro Minas Caixa - Regional Venda Nova | K29: 2302.1012201171.216.449051.S.500 | L29: 2302 | M29: FUNDO MUNICIPAL DE SAÚDE | N29: 10 | O29: SAÚDE | P29: 122 | Q29: ADMINISTRAÇÃO GERAL | R29: 0117 | S29: GESTÃO DO SUS | T29: 1216 | U29: CONSTRUÇÃO, AMPLIAÇÃO E REFORMA DE UNIDADES DE SAÚDE | V29: 449051 | W29: Despesa de capital | X29: Investimentos | Y29: 500 | Z29: FMS/SMOBI | AA29: 90000 | AB29: 0 | AC29: 0 | AD29: 0 | AF29: 1 | AG29: 1 | AH29: 0322 | AI29: =IF(AH29="","",IFERROR(RIGHT("0000"&AH29,4)&" - "&UPPER(_xlfn.XLOOKUP(RIGHT("0000"&AH29,4),CODEBOOK_CAP!$C$2:$C$212,CODEBOOK_CAP!$D$2:$D$212)),"Código CAP não encontrado")) -> 0322 - ESTRUTURAS, HOSPITAIS, CLÍNICAS | AJ29: =IF(AH29="","",IFERROR(_xlfn.XLOOKUP(RIGHT("0000"&AH29,4),CODEBOOK_CAP!$C$2:$C$212,CODEBOOK_CAP!$E$2:$E$212),"Código CAP não encontrado")) -> Observações relacionadas as estruturas do sistema de saúde, como a construção de hospitais, postos de saúde, construção de maternidades, laboratórios, centros de saúde avançado, SAMU, Ambulâncias, UTI Móveis, leitos, compra de equipamentos médicos, Raio X, Ultrasom, equipamentos de diálise, capacidade de atendimento, estrutura e funcionamento de equipamentos públicos de saúde. | AK29: 1 | AL29: Rua capitão Sérgio Pires, 226 - Bairro Minas Caixa - Regional Venda Nova | AM29: 1 | AN29: 1 | AO29: Centro de Saúde Minas Caixa (Rua capitão Sérgio Pires, 226 - Bairro Minas Caixa - Regional Venda Nova) | AP29: 0 | AR29: 0 | AT29: Revisado | AU29: Alta | AV29: 46214
A30: 2023_BIM_DA_AMBULANCIA_818_01 | B30: 2023 | C30: 597 | D30: emendas-2023-27-11-2025.xlsx | E30: 2023_BIM_DA_AMBULANCIA | F30: 818 | G30: EM EXECUÇÃO | H30: Bim da Ambulância | J30: À aquisição de materiais permanentes para o Centro de Saúde Alameda dos Ipês, na Regional Venda Nova, situado à rua Ministro Oliveira Salazar, 1186 - Bairro Santa Mônica | K30: 2302.1030101572.690.449052.S.500 | L30: 2302 | M30: FUNDO MUNICIPAL DE SAÚDE | N30: 10 | O30: SAÚDE | P30: 301 | Q30: ATENÇÃO BÁSICA | R30: 0157 | S30: ATENÇÃO PRIMÁRIA À SAÚDE | T30: 2690 | U30: ATENÇÃO PRIMÁRIA À SAÚDE | V30: 449052 | W30: Despesa de capital | X30: Investimentos | Y30: 500 | Z30: FMS | AA30: 60000 | AB30: 51738.5 | AC30: 51738.5 | AD30: 51738.5 | AF30: 1 | AG30: 1 | AH30: 0322 | AI30: =IF(AH30="","",IFERROR(RIGHT("0000"&AH30,4)&" - "&UPPER(_xlfn.XLOOKUP(RIGHT("0000"&AH30,4),CODEBOOK_CAP!$C$2:$C$212,CODEBOOK_CAP!$D$2:$D$212)),"Código CAP não encontrado")) -> 0322 - ESTRUTURAS, HOSPITAIS, CLÍNICAS | AJ30: =IF(AH30="","",IFERROR(_xlfn.XLOOKUP(RIGHT("0000"&AH30,4),CODEBOOK_CAP!$C$2:$C$212,CODEBOOK_CAP!$E$2:$E$212),"Código CAP não encontrado")) -> Observações relacionadas as estruturas do sistema de saúde, como a construção de hospitais, postos de saúde, construção de maternidades, laboratórios, centros de saúde avançado, SAMU, Ambulâncias, UTI Móveis, leitos, compra de equipamentos médicos, Raio X, Ultrasom, equipamentos de diálise, capacidade de atendimento, estrutura e funcionamento de equipamentos públicos de saúde. | AK30: 1 | AL30: Regional Venda Nova, situado à rua Ministro Oliveira Salazar, 1186 - Bairro Santa Mônica | AM30: 1 | AN30: 1 | AO30: Centro de Saúde Alameda dos Ipês (Regional Venda Nova, situado à rua Ministro Oliveira Salazar, 1186 - Bairro Santa Mônica) | AP30: 0 | AR30: 0 | AT30: Revisado | AU30: Alta | AV30: 46214
A31: 2023_BIM_DA_AMBULANCIA_819_01 | B31: 2023 | C31: 598 | D31: emendas-2023-27-11-2025.xlsx | E31: 2023_BIM_DA_AMBULANCIA | F31: 819 | G31: IMPEDIMENTO TÉCNICO | H31: Bim da Ambulância | J31: Obra de Ampliação de Consultórios no Centro de Saúde Andradas, situado à Rua Mariana Amélia de Azevedo, 21 - Bairro São João Batista. | K31: 2302.1012201171.216.449051.S.500 | L31: 2302 | M31: FUNDO MUNICIPAL DE SAÚDE | N31: 10 | O31: SAÚDE | P31: 122 | Q31: ADMINISTRAÇÃO GERAL | R31: 0117 | S31: GESTÃO DO SUS | T31: 1216 | U31: CONSTRUÇÃO, AMPLIAÇÃO E REFORMA DE UNIDADES DE SAÚDE | V31: 449051 | W31: Despesa de capital | X31: Investimentos | Y31: 500 | Z31: FMS/SMOBI | AA31: 100000 | AB31: 0 | AC31: 0 | AD31: 0 | AF31: 1 | AG31: 1 | AH31: 0322 | AI31: =IF(AH31="","",IFERROR(RIGHT("0000"&AH31,4)&" - "&UPPER(_xlfn.XLOOKUP(RIGHT("0000"&AH31,4),CODEBOOK_CAP!$C$2:$C$212,CODEBOOK_CAP!$D$2:$D$212)),"Código CAP não encontrado")) -> 0322 - ESTRUTURAS, HOSPITAIS, CLÍNICAS | AJ31: =IF(AH31="","",IFERROR(_xlfn.XLOOKUP(RIGHT("0000"&AH31,4),CODEBOOK_CAP!$C$2:$C$212,CODEBOOK_CAP!$E$2:$E$212),"Código CAP não encontrado")) -> Observações relacionadas as estruturas do sistema de saúde, como a construção de hospitais, postos de saúde, construção de maternidades, laboratórios, centros de saúde avançado, SAMU, Ambulâncias, UTI Móveis, leitos, compra de equipamentos médicos, Raio X, Ultrasom, equipamentos de diálise, capacidade de atendimento, estrutura e funcionamento de equipamentos públicos de saúde. | AK31: 1 | AL31: Rua Mariana Amélia de Azevedo, 21 - Bairro São João Batista. | AM31: 1 | AN31: 1 | AO31: Centro de Saúde Andradas (Rua Mariana Amélia de Azevedo, 21 - Bairro São João Batista.) | AP31: 0 | AR31: 0 | AT31: Revisado | AU31: Alta | AV31: 46214
A32: 2023_BIM_DA_AMBULANCIA_820_01 | B32: 2023 | C32: 599 | D32: emendas-2023-27-11-2025.xlsx | E32: 2023_BIM_DA_AMBULANCIA | F32: 820 | G32: CONCLUÍDO | H32: Bim da Ambulância | J32: Recurso destinado para a Obra em andamento da reforma do Centro de Saúde Céu Azul, localizado à Rua Alice Marques, 187 - Bairro Céu Azul | K32: 2302.1012201171.216.449051.S.500 | L32: 2302 | M32: FUNDO MUNICIPAL DE SAÚDE | N32: 10 | O32: SAÚDE | P32: 122 | Q32: ADMINISTRAÇÃO GERAL | R32: 0117 | S32: GESTÃO DO SUS | T32: 1216 | U32: CONSTRUÇÃO, AMPLIAÇÃO E REFORMA DE UNIDADES DE SAÚDE | V32: 449051 | W32: Despesa de capital | X32: Investimentos | Y32: 500 | Z32: FMS/SMOBI | AA32: 50000 | AB32: 32708.75 | AC32: 32708.75 | AD32: 32708.75 | AF32: 1 | AG32: 1 | AH32: 0322 | AI32: =IF(AH32="","",IFERROR(RIGHT("0000"&AH32,4)&" - "&UPPER(_xlfn.XLOOKUP(RIGHT("0000"&AH32,4),CODEBOOK_CAP!$C$2:$C$212,CODEBOOK_CAP!$D$2:$D$212)),"Código CAP não encontrado")) -> 0322 - ESTRUTURAS, HOSPITAIS, CLÍNICAS | AJ32: =IF(AH32="","",IFERROR(_xlfn.XLOOKUP(RIGHT("0000"&AH32,4),CODEBOOK_CAP!$C$2:$C$212,CODEBOOK_CAP!$E$2:$E$212),"Código CAP não encontrado")) -> Observações relacionadas as estruturas do sistema de saúde, como a construção de hospitais, postos de saúde, construção de maternidades, laboratórios, centros de saúde avançado, SAMU, Ambulâncias, UTI Móveis, leitos, compra de equipamentos médicos, Raio X, Ultrasom, equipamentos de diálise, capacidade de atendimento, estrutura e funcionamento de equipamentos públicos de saúde. | AK32: 1 | AL32: Rua Alice Marques, 187 - Bairro Céu Azul | AM32: 1 | AN32: 1 | AO32: Centro de Saúde Céu Azul (Rua Alice Marques, 187 - Bairro Céu Azul) | AP32: 0 | AR32: 0 | AT32: Revisado | AU32: Alta | AV32: 46214
A33: 2023_BIM_DA_AMBULANCIA_822_01 | B33: 2023 | C33: 601 | D33: emendas-2023-27-11-2025.xlsx | E33: 2023_BIM_DA_AMBULANCIA | F33: 822 | G33: CONCLUÍDO | H33: Bim da Ambulância | J33: À aquisição de materiais permanentes para o Centro de Saúde Céu Azul, situado à rua: Alice Marques, 187 - Bairro Céu Azul | K33: 2302.1030101572.690.449052.S.500 | L33: 2302 | M33: FUNDO MUNICIPAL DE SAÚDE | N33: 10 | O33: SAÚDE | P33: 301 | Q33: ATENÇÃO BÁSICA | R33: 0157 | S33: ATENÇÃO PRIMÁRIA À SAÚDE | T33: 2690 | U33: ATENÇÃO PRIMÁRIA À SAÚDE | V33: 449052 | W33: Despesa de capital | X33: Investimentos | Y33: 500 | Z33: FMS | AA33: 20000 | AB33: 18930.98 | AC33: 18930.98 | AD33: 18930.98 | AF33: 1 | AG33: 1 | AH33: 0322 | AI33: =IF(AH33="","",IFERROR(RIGHT("0000"&AH33,4)&" - "&UPPER(_xlfn.XLOOKUP(RIGHT("0000"&AH33,4),CODEBOOK_CAP!$C$2:$C$212,CODEBOOK_CAP!$D$2:$D$212)),"Código CAP não encontrado")) -> 0322 - ESTRUTURAS, HOSPITAIS, CLÍNICAS | AJ33: =IF(AH33="","",IFERROR(_xlfn.XLOOKUP(RIGHT("0000"&AH33,4),CODEBOOK_CAP!$C$2:$C$212,CODEBOOK_CAP!$E$2:$E$212),"Código CAP não encontrado")) -> Observações relacionadas as estruturas do sistema de saúde, como a construção de hospitais, postos de saúde, construção de maternidades, laboratórios, centros de saúde avançado, SAMU, Ambulâncias, UTI Móveis, leitos, compra de equipamentos médicos, Raio X, Ultrasom, equipamentos de diálise, capacidade de atendimento, estrutura e funcionamento de equipamentos públicos de saúde. | AK33: 1 | AL33: rua: Alice Marques, 187 - Bairro Céu Azul | AM33: 1 | AN33: 1 | AO33: Centro de Saúde Céu Azul (rua: Alice Marques, 187 - Bairro Céu Azul) | AP33: 0 | AR33: 0 | AT33: Revisado | AU33: Alta | AV33: 46214
